2023-02-08 19:13:35.433 | ERROR    | __main__:<module>:110 - The number of file parts is invalid (caused by SendMediaRequest)
Traceback (most recent call last):

> File "F:\с sd флешки\telegram_bot_smm\main.py", line 108, in <module>
    main()
    └ <function main at 0x00000241E4C55360>

  File "F:\с sd флешки\telegram_bot_smm\main.py", line 86, in main
    sending_messages_to_a_personal_account_chat()
    └ <function sending_messages_to_a_personal_account_chat at 0x00000241E4446EF0>

  File "F:\с sd флешки\telegram_bot_smm\system\menu\sending_messages_menu.py", line 58, in sending_messages_to_a_personal_account_chat
    sending_messages_to_a_personal_account_chat()  # После отработки функции перезапускам скрипт
    └ <function sending_messages_to_a_personal_account_chat at 0x00000241E4446EF0>

  File "F:\с sd флешки\telegram_bot_smm\system\menu\sending_messages_menu.py", line 67, in sending_messages_to_a_personal_account_chat
    sending_files_via_chats()
    └ <function sending_files_via_chats at 0x00000241E4447490>

  File "F:\с sd флешки\telegram_bot_smm\system\actions\send_mess_chat\chat_dialog.py", line 52, in sending_files_via_chats
    client.send_file(groups_wr, f"setting_user/files_to_send/{link_to_the_file}")
    │      │         └ 'https://t.me/dev_tg_pro'
    │      └ <function UploadMethods.send_file at 0x00000241E37A1090>
    └ <telethon.client.telegramclient.TelegramClient object at 0x00000241E46EBA90>

  File "C:\Users\zhvit\AppData\Local\Programs\Python\Python310\lib\site-packages\telethon\sync.py", line 39, in syncified
    return loop.run_until_complete(coro)
           │    │                  └ <coroutine object UploadMethods.send_file at 0x00000241E46A55B0>
           │    └ <function BaseEventLoop.run_until_complete at 0x00000241E23F9AB0>
           └ <ProactorEventLoop running=False closed=False debug=False>

  File "C:\Users\zhvit\AppData\Local\Programs\Python\Python310\lib\asyncio\base_events.py", line 646, in run_until_complete
    return future.result()
           │      └ <method 'result' of '_asyncio.Task' objects>
           └ <Task finished name='Task-105' coro=<UploadMethods.send_file() done, defined at C:\Users\zhvit\AppData\Local\Programs\Python\...

  File "C:\Users\zhvit\AppData\Local\Programs\Python\Python310\lib\site-packages\telethon\client\uploads.py", line 412, in send_file
    return self._get_response_message(request, await self(request), entity)
           │    │                     │              │    │         └ <telethon.tl.types.InputPeerChannel object at 0x00000241E46EB4F0>
           │    │                     │              │    └ <telethon.tl.functions.messages.SendMediaRequest object at 0x00000241E46EB190>
           │    │                     │              └ <telethon.client.telegramclient.TelegramClient object at 0x00000241E46EBA90>
           │    │                     └ <telethon.tl.functions.messages.SendMediaRequest object at 0x00000241E46EB190>
           │    └ <function MessageParseMethods._get_response_message at 0x00000241E3026830>
           └ <telethon.client.telegramclient.TelegramClient object at 0x00000241E46EBA90>

  File "C:\Users\zhvit\AppData\Local\Programs\Python\Python310\lib\site-packages\telethon\client\users.py", line 30, in __call__
    return await self._call(self._sender, request, ordered=ordered)
                 │    │     │    │        │                └ False
                 │    │     │    │        └ <telethon.tl.functions.messages.SendMediaRequest object at 0x00000241E46EB190>
                 │    │     │    └ <telethon.network.mtprotosender.MTProtoSender object at 0x00000241E46EB5B0>
                 │    │     └ <telethon.client.telegramclient.TelegramClient object at 0x00000241E46EBA90>
                 │    └ <function UserMethods._call at 0x00000241E3027C70>
                 └ <telethon.client.telegramclient.TelegramClient object at 0x00000241E46EBA90>

  File "C:\Users\zhvit\AppData\Local\Programs\Python\Python310\lib\site-packages\telethon\client\users.py", line 84, in _call
    result = await future
                   └ <Future finished exception=FilePartsInvalidError('The number of file parts is invalid (caused by SendMediaRequest)')>

telethon.errors.rpcerrorlist.FilePartsInvalidError: The number of file parts is invalid (caused by SendMediaRequest)
2023-03-08 20:51:03.420 | ERROR    | __main__:<module>:21 - parameters are of unsupported type
Traceback (most recent call last):

> File "G:\с sd флешки\telegram_bot_smm\main.py", line 19, in <module>
    launching_the_program_with_account_verification()
    └ <function launching_the_program_with_account_verification at 0x00000202B8761870>

  File "G:\с sd флешки\telegram_bot_smm\main.py", line 14, in launching_the_program_with_account_verification
    main_menu()
    └ <function main_menu at 0x00000202B87615A0>

  File "G:\с sd флешки\telegram_bot_smm\system\menu\main_menu.py", line 84, in main_menu
    program_settings()
    └ <function program_settings at 0x00000202B87617E0>

  File "G:\с sd флешки\telegram_bot_smm\system\menu\main_menu.py", line 440, in program_settings
    proxy_data = creating_the_main_window_for_proxy_data_entry()
                 └ <function creating_the_main_window_for_proxy_data_entry at 0x00000202B855C940>

  File "G:\с sd флешки\telegram_bot_smm\system\sqlite_working_tools\sqlite_working_tools.py", line 51, in writing_proxy_data_to_the_database
    cursor.executemany("INSERT INTO proxy(proxy_type, addr, port, username, password, rdns) "
    │      └ <method 'executemany' of 'sqlite3.Cursor' objects>
    └ <sqlite3.Cursor object at 0x00000202B8D8FEC0>

ValueError: parameters are of unsupported type
2023-03-08 20:51:03.420 | ERROR    | __main__:<module>:21 - parameters are of unsupported type
Traceback (most recent call last):

> File "G:\с sd флешки\telegram_bot_smm\main.py", line 19, in <module>
    launching_the_program_with_account_verification()
    └ <function launching_the_program_with_account_verification at 0x00000202B8761870>

  File "G:\с sd флешки\telegram_bot_smm\main.py", line 14, in launching_the_program_with_account_verification
    main_menu()
    └ <function main_menu at 0x00000202B87615A0>

  File "G:\с sd флешки\telegram_bot_smm\system\menu\main_menu.py", line 84, in main_menu
    program_settings()
    └ <function program_settings at 0x00000202B87617E0>

  File "G:\с sd флешки\telegram_bot_smm\system\menu\main_menu.py", line 440, in program_settings
    proxy_data = creating_the_main_window_for_proxy_data_entry()
                 └ <function creating_the_main_window_for_proxy_data_entry at 0x00000202B855C940>

  File "G:\с sd флешки\telegram_bot_smm\system\sqlite_working_tools\sqlite_working_tools.py", line 51, in writing_proxy_data_to_the_database
    cursor.executemany("INSERT INTO proxy(proxy_type, addr, port, username, password, rdns) "
    │      └ <method 'executemany' of 'sqlite3.Cursor' objects>
    └ <sqlite3.Cursor object at 0x00000202B8D8FEC0>

ValueError: parameters are of unsupported type
2023-03-08 20:51:46.165 | ERROR    | __main__:<module>:21 - parameters are of unsupported type
Traceback (most recent call last):

> File "G:\с sd флешки\telegram_bot_smm\main.py", line 19, in <module>
    launching_the_program_with_account_verification()
    └ <function launching_the_program_with_account_verification at 0x000001BBC8C41870>

  File "G:\с sd флешки\telegram_bot_smm\main.py", line 14, in launching_the_program_with_account_verification
    main_menu()
    └ <function main_menu at 0x000001BBC8C415A0>

  File "G:\с sd флешки\telegram_bot_smm\system\menu\main_menu.py", line 84, in main_menu
    program_settings()
    └ <function program_settings at 0x000001BBC8C417E0>

  File "G:\с sd флешки\telegram_bot_smm\system\menu\main_menu.py", line 441, in program_settings
    writing_proxy_data_to_the_database(proxy=proxy_data)
    │                                        └ None
    └ <function writing_proxy_data_to_the_database at 0x000001BBC7DFC430>

  File "G:\с sd флешки\telegram_bot_smm\system\sqlite_working_tools\sqlite_working_tools.py", line 51, in writing_proxy_data_to_the_database
    cursor.executemany("INSERT INTO proxy(proxy_type, addr, port, username, password, rdns) "
    │      └ <method 'executemany' of 'sqlite3.Cursor' objects>
    └ <sqlite3.Cursor object at 0x000001BBC926FC40>

ValueError: parameters are of unsupported type
2023-03-08 21:01:19.085 | ERROR    | __main__:<module>:21 - parameters are of unsupported type
Traceback (most recent call last):

> File "G:\с sd флешки\telegram_bot_smm\main.py", line 19, in <module>
    launching_the_program_with_account_verification()
    └ <function launching_the_program_with_account_verification at 0x000001D3258B1990>

  File "G:\с sd флешки\telegram_bot_smm\main.py", line 14, in launching_the_program_with_account_verification
    main_menu()
    └ <function main_menu at 0x000001D3258B16C0>

  File "G:\с sd флешки\telegram_bot_smm\system\menu\main_menu.py", line 84, in main_menu
    program_settings()
    └ <function program_settings at 0x000001D3258B1900>

  File "G:\с sd флешки\telegram_bot_smm\system\menu\main_menu.py", line 441, in program_settings
    writing_proxy_data_to_the_database(proxy=proxy_data)
    │                                        └ None
    └ <function writing_proxy_data_to_the_database at 0x000001D324A64550>

  File "G:\с sd флешки\telegram_bot_smm\system\sqlite_working_tools\sqlite_working_tools.py", line 51, in writing_proxy_data_to_the_database
    cursor.executemany("INSERT INTO proxy(proxy_type, addr, port, username, password, rdns) "
    │      └ <method 'executemany' of 'sqlite3.Cursor' objects>
    └ <sqlite3.Cursor object at 0x000001D325EEFCC0>

ValueError: parameters are of unsupported type
2023-03-08 21:01:19.085 | ERROR    | __main__:<module>:21 - parameters are of unsupported type
Traceback (most recent call last):

> File "G:\с sd флешки\telegram_bot_smm\main.py", line 19, in <module>
    launching_the_program_with_account_verification()
    └ <function launching_the_program_with_account_verification at 0x000001D3258B1990>

  File "G:\с sd флешки\telegram_bot_smm\main.py", line 14, in launching_the_program_with_account_verification
    main_menu()
    └ <function main_menu at 0x000001D3258B16C0>

  File "G:\с sd флешки\telegram_bot_smm\system\menu\main_menu.py", line 84, in main_menu
    program_settings()
    └ <function program_settings at 0x000001D3258B1900>

  File "G:\с sd флешки\telegram_bot_smm\system\menu\main_menu.py", line 441, in program_settings
    writing_proxy_data_to_the_database(proxy=proxy_data)
    │                                        └ None
    └ <function writing_proxy_data_to_the_database at 0x000001D324A64550>

  File "G:\с sd флешки\telegram_bot_smm\system\sqlite_working_tools\sqlite_working_tools.py", line 51, in writing_proxy_data_to_the_database
    cursor.executemany("INSERT INTO proxy(proxy_type, addr, port, username, password, rdns) "
    │      └ <method 'executemany' of 'sqlite3.Cursor' objects>
    └ <sqlite3.Cursor object at 0x000001D325EEFCC0>

ValueError: parameters are of unsupported type
2023-04-20 00:00:57.798 | ERROR    | __main__:<module>:22 - Error binding parameter 0 - probably unsupported type.
Traceback (most recent call last):

> File "C:\Users\zhvit\YandexDisk\telegram_bot_smm\main.py", line 20, in <module>
    launching_the_program_with_account_verification()
    └ <function launching_the_program_with_account_verification at 0x000001AA9EC2E4D0>

  File "C:\Users\zhvit\YandexDisk\telegram_bot_smm\main.py", line 15, in launching_the_program_with_account_verification
    main_menu()
    └ <function main_menu at 0x000001AA9EC2E170>

  File "C:\Users\zhvit\YandexDisk\telegram_bot_smm\system\menu\main_menu.py", line 61, in main_menu
    telegram_parsing_menu()
    └ <function telegram_parsing_menu at 0x000001AA9EC2E0E0>

  File "C:\Users\zhvit\YandexDisk\telegram_bot_smm\system\menu\main_menu.py", line 194, in telegram_parsing_menu
    parsing_of_groups_to_which_the_account_is_subscribed()
    └ <function parsing_of_groups_to_which_the_account_is_subscribed at 0x000001AA9E45F520>

  File "C:\Users\zhvit\YandexDisk\telegram_bot_smm\system\actions\pars\parsing_account_groups_and_channels.py", line 28, in parsing_of_groups_to_which_the_account_is_subscribed
    writing_data_to_the_db(creating_a_table, writing_data_to_a_table, groups)
    │                      │                 │                        └ [[-1001545235329, 'Барановичский район', 'Барановичский районный исполнительный комитет', 'https://t.me/barrai'], [-100173236...
    │                      │                 └ 'INSERT INTO groups_and_channels (id, title, about, link) VALUES (?, ?, ?, ?)'
    │                      └ 'CREATE TABLE IF NOT EXISTS groups_and_channels(id, title, about, link)'
    └ <function writing_data_to_the_db at 0x000001AA9E0E2F80>

  File "C:\Users\zhvit\YandexDisk\telegram_bot_smm\system\sqlite_working_tools\sqlite_working_tools.py", line 72, in writing_data_to_the_db
    cursor.executemany(writing_data_to_a_table, (entities,))
    │      │           │                         └ [[-1001545235329, 'Барановичский район', 'Барановичский районный исполнительный комитет', 'https://t.me/barrai'], [-100173236...
    │      │           └ 'INSERT INTO groups_and_channels (id, title, about, link) VALUES (?, ?, ?, ?)'
    │      └ <method 'executemany' of 'sqlite3.Cursor' objects>
    └ <sqlite3.Cursor object at 0x000001AA9E5FEBC0>

sqlite3.InterfaceError: Error binding parameter 0 - probably unsupported type.
2023-04-20 00:00:57.798 | ERROR    | __main__:<module>:22 - Error binding parameter 0 - probably unsupported type.
Traceback (most recent call last):

> File "C:\Users\zhvit\YandexDisk\telegram_bot_smm\main.py", line 20, in <module>
    launching_the_program_with_account_verification()
    └ <function launching_the_program_with_account_verification at 0x000001AA9EC2E4D0>

  File "C:\Users\zhvit\YandexDisk\telegram_bot_smm\main.py", line 15, in launching_the_program_with_account_verification
    main_menu()
    └ <function main_menu at 0x000001AA9EC2E170>

  File "C:\Users\zhvit\YandexDisk\telegram_bot_smm\system\menu\main_menu.py", line 61, in main_menu
    telegram_parsing_menu()
    └ <function telegram_parsing_menu at 0x000001AA9EC2E0E0>

  File "C:\Users\zhvit\YandexDisk\telegram_bot_smm\system\menu\main_menu.py", line 194, in telegram_parsing_menu
    parsing_of_groups_to_which_the_account_is_subscribed()
    └ <function parsing_of_groups_to_which_the_account_is_subscribed at 0x000001AA9E45F520>

  File "C:\Users\zhvit\YandexDisk\telegram_bot_smm\system\actions\pars\parsing_account_groups_and_channels.py", line 28, in parsing_of_groups_to_which_the_account_is_subscribed
    writing_data_to_the_db(creating_a_table, writing_data_to_a_table, groups)
    │                      │                 │                        └ [[-1001545235329, 'Барановичский район', 'Барановичский районный исполнительный комитет', 'https://t.me/barrai'], [-100173236...
    │                      │                 └ 'INSERT INTO groups_and_channels (id, title, about, link) VALUES (?, ?, ?, ?)'
    │                      └ 'CREATE TABLE IF NOT EXISTS groups_and_channels(id, title, about, link)'
    └ <function writing_data_to_the_db at 0x000001AA9E0E2F80>

  File "C:\Users\zhvit\YandexDisk\telegram_bot_smm\system\sqlite_working_tools\sqlite_working_tools.py", line 72, in writing_data_to_the_db
    cursor.executemany(writing_data_to_a_table, (entities,))
    │      │           │                         └ [[-1001545235329, 'Барановичский район', 'Барановичский районный исполнительный комитет', 'https://t.me/barrai'], [-100173236...
    │      │           └ 'INSERT INTO groups_and_channels (id, title, about, link) VALUES (?, ?, ?, ?)'
    │      └ <method 'executemany' of 'sqlite3.Cursor' objects>
    └ <sqlite3.Cursor object at 0x000001AA9E5FEBC0>

sqlite3.InterfaceError: Error binding parameter 0 - probably unsupported type.
2023-04-20 00:02:54.714 | ERROR    | __main__:<module>:22 - unrecognized token: ":"
Traceback (most recent call last):

> File "C:\Users\zhvit\YandexDisk\telegram_bot_smm\main.py", line 20, in <module>
    launching_the_program_with_account_verification()
    └ <function launching_the_program_with_account_verification at 0x00000283411167A0>

  File "C:\Users\zhvit\YandexDisk\telegram_bot_smm\main.py", line 15, in launching_the_program_with_account_verification
    main_menu()
    └ <function main_menu at 0x0000028341116440>

  File "C:\Users\zhvit\YandexDisk\telegram_bot_smm\system\menu\main_menu.py", line 61, in main_menu
    telegram_parsing_menu()
    └ <function telegram_parsing_menu at 0x00000283411163B0>

  File "C:\Users\zhvit\YandexDisk\telegram_bot_smm\system\menu\main_menu.py", line 194, in telegram_parsing_menu
    parsing_of_groups_to_which_the_account_is_subscribed()
    └ <function parsing_of_groups_to_which_the_account_is_subscribed at 0x000002834094F5B0>

  File "C:\Users\zhvit\YandexDisk\telegram_bot_smm\system\actions\pars\parsing_account_groups_and_channels.py", line 28, in parsing_of_groups_to_which_the_account_is_subscribed
    writing_data_to_the_db(creating_a_table, writing_data_to_a_table, groups)
    │                      │                 │                        └ [[-1001545235329, 'Барановичский район', 'Барановичский районный исполнительный комитет', 'https://t.me/barrai'], [-100173236...
    │                      │                 └ 'INSERT INTO groups_and_channels (id, title, about, link) VALUES (?, ?, ?, ?::text)'
    │                      └ 'CREATE TABLE IF NOT EXISTS groups_and_channels(id, title, about, link)'
    └ <function writing_data_to_the_db at 0x00000283405D2DD0>

  File "C:\Users\zhvit\YandexDisk\telegram_bot_smm\system\sqlite_working_tools\sqlite_working_tools.py", line 72, in writing_data_to_the_db
    cursor.executemany(writing_data_to_a_table, (entities,))
    │      │           │                         └ [[-1001545235329, 'Барановичский район', 'Барановичский районный исполнительный комитет', 'https://t.me/barrai'], [-100173236...
    │      │           └ 'INSERT INTO groups_and_channels (id, title, about, link) VALUES (?, ?, ?, ?::text)'
    │      └ <method 'executemany' of 'sqlite3.Cursor' objects>
    └ <sqlite3.Cursor object at 0x0000028340AE2A40>

sqlite3.OperationalError: unrecognized token: ":"
2023-04-20 00:02:54.714 | ERROR    | __main__:<module>:22 - unrecognized token: ":"
Traceback (most recent call last):

> File "C:\Users\zhvit\YandexDisk\telegram_bot_smm\main.py", line 20, in <module>
    launching_the_program_with_account_verification()
    └ <function launching_the_program_with_account_verification at 0x00000283411167A0>

  File "C:\Users\zhvit\YandexDisk\telegram_bot_smm\main.py", line 15, in launching_the_program_with_account_verification
    main_menu()
    └ <function main_menu at 0x0000028341116440>

  File "C:\Users\zhvit\YandexDisk\telegram_bot_smm\system\menu\main_menu.py", line 61, in main_menu
    telegram_parsing_menu()
    └ <function telegram_parsing_menu at 0x00000283411163B0>

  File "C:\Users\zhvit\YandexDisk\telegram_bot_smm\system\menu\main_menu.py", line 194, in telegram_parsing_menu
    parsing_of_groups_to_which_the_account_is_subscribed()
    └ <function parsing_of_groups_to_which_the_account_is_subscribed at 0x000002834094F5B0>

  File "C:\Users\zhvit\YandexDisk\telegram_bot_smm\system\actions\pars\parsing_account_groups_and_channels.py", line 28, in parsing_of_groups_to_which_the_account_is_subscribed
    writing_data_to_the_db(creating_a_table, writing_data_to_a_table, groups)
    │                      │                 │                        └ [[-1001545235329, 'Барановичский район', 'Барановичский районный исполнительный комитет', 'https://t.me/barrai'], [-100173236...
    │                      │                 └ 'INSERT INTO groups_and_channels (id, title, about, link) VALUES (?, ?, ?, ?::text)'
    │                      └ 'CREATE TABLE IF NOT EXISTS groups_and_channels(id, title, about, link)'
    └ <function writing_data_to_the_db at 0x00000283405D2DD0>

  File "C:\Users\zhvit\YandexDisk\telegram_bot_smm\system\sqlite_working_tools\sqlite_working_tools.py", line 72, in writing_data_to_the_db
    cursor.executemany(writing_data_to_a_table, (entities,))
    │      │           │                         └ [[-1001545235329, 'Барановичский район', 'Барановичский районный исполнительный комитет', 'https://t.me/barrai'], [-100173236...
    │      │           └ 'INSERT INTO groups_and_channels (id, title, about, link) VALUES (?, ?, ?, ?::text)'
    │      └ <method 'executemany' of 'sqlite3.Cursor' objects>
    └ <sqlite3.Cursor object at 0x0000028340AE2A40>

sqlite3.OperationalError: unrecognized token: ":"
2023-04-20 00:05:15.767 | ERROR    | __main__:<module>:22 - Error binding parameter 0 - probably unsupported type.
Traceback (most recent call last):

> File "C:\Users\zhvit\YandexDisk\telegram_bot_smm\main.py", line 20, in <module>
    launching_the_program_with_account_verification()
    └ <function launching_the_program_with_account_verification at 0x0000019BA5F36710>

  File "C:\Users\zhvit\YandexDisk\telegram_bot_smm\main.py", line 15, in launching_the_program_with_account_verification
    main_menu()
    └ <function main_menu at 0x0000019BA5F363B0>

  File "C:\Users\zhvit\YandexDisk\telegram_bot_smm\system\menu\main_menu.py", line 61, in main_menu
    telegram_parsing_menu()
    └ <function telegram_parsing_menu at 0x0000019BA5F36320>

  File "C:\Users\zhvit\YandexDisk\telegram_bot_smm\system\menu\main_menu.py", line 194, in telegram_parsing_menu
    parsing_of_groups_to_which_the_account_is_subscribed()
    └ <function parsing_of_groups_to_which_the_account_is_subscribed at 0x0000019BA576F520>

  File "C:\Users\zhvit\YandexDisk\telegram_bot_smm\system\actions\pars\parsing_account_groups_and_channels.py", line 28, in parsing_of_groups_to_which_the_account_is_subscribed
    writing_data_to_the_db(creating_a_table, writing_data_to_a_table, groups)
    │                      │                 │                        └ [[-1001545235329, 'Барановичский район', 'Барановичский районный исполнительный комитет', 'https://t.me/barrai'], [-100173236...
    │                      │                 └ 'INSERT INTO groups_and_channels (id, title, about, link) VALUES (?, ?, ?, ?)'
    │                      └ 'CREATE TABLE IF NOT EXISTS groups_and_channels(id, title, about, link)'
    └ <function writing_data_to_the_db at 0x0000019BA53F2DD0>

  File "C:\Users\zhvit\YandexDisk\telegram_bot_smm\system\sqlite_working_tools\sqlite_working_tools.py", line 72, in writing_data_to_the_db
    cursor.executemany(writing_data_to_a_table, (entities,))
    │      │           │                         └ [[-1001545235329, 'Барановичский район', 'Барановичский районный исполнительный комитет', 'https://t.me/barrai'], [-100173236...
    │      │           └ 'INSERT INTO groups_and_channels (id, title, about, link) VALUES (?, ?, ?, ?)'
    │      └ <method 'executemany' of 'sqlite3.Cursor' objects>
    └ <sqlite3.Cursor object at 0x0000019BA5902AC0>

sqlite3.InterfaceError: Error binding parameter 0 - probably unsupported type.
2023-04-20 00:05:15.767 | ERROR    | __main__:<module>:22 - Error binding parameter 0 - probably unsupported type.
Traceback (most recent call last):

> File "C:\Users\zhvit\YandexDisk\telegram_bot_smm\main.py", line 20, in <module>
    launching_the_program_with_account_verification()
    └ <function launching_the_program_with_account_verification at 0x0000019BA5F36710>

  File "C:\Users\zhvit\YandexDisk\telegram_bot_smm\main.py", line 15, in launching_the_program_with_account_verification
    main_menu()
    └ <function main_menu at 0x0000019BA5F363B0>

  File "C:\Users\zhvit\YandexDisk\telegram_bot_smm\system\menu\main_menu.py", line 61, in main_menu
    telegram_parsing_menu()
    └ <function telegram_parsing_menu at 0x0000019BA5F36320>

  File "C:\Users\zhvit\YandexDisk\telegram_bot_smm\system\menu\main_menu.py", line 194, in telegram_parsing_menu
    parsing_of_groups_to_which_the_account_is_subscribed()
    └ <function parsing_of_groups_to_which_the_account_is_subscribed at 0x0000019BA576F520>

  File "C:\Users\zhvit\YandexDisk\telegram_bot_smm\system\actions\pars\parsing_account_groups_and_channels.py", line 28, in parsing_of_groups_to_which_the_account_is_subscribed
    writing_data_to_the_db(creating_a_table, writing_data_to_a_table, groups)
    │                      │                 │                        └ [[-1001545235329, 'Барановичский район', 'Барановичский районный исполнительный комитет', 'https://t.me/barrai'], [-100173236...
    │                      │                 └ 'INSERT INTO groups_and_channels (id, title, about, link) VALUES (?, ?, ?, ?)'
    │                      └ 'CREATE TABLE IF NOT EXISTS groups_and_channels(id, title, about, link)'
    └ <function writing_data_to_the_db at 0x0000019BA53F2DD0>

  File "C:\Users\zhvit\YandexDisk\telegram_bot_smm\system\sqlite_working_tools\sqlite_working_tools.py", line 72, in writing_data_to_the_db
    cursor.executemany(writing_data_to_a_table, (entities,))
    │      │           │                         └ [[-1001545235329, 'Барановичский район', 'Барановичский районный исполнительный комитет', 'https://t.me/barrai'], [-100173236...
    │      │           └ 'INSERT INTO groups_and_channels (id, title, about, link) VALUES (?, ?, ?, ?)'
    │      └ <method 'executemany' of 'sqlite3.Cursor' objects>
    └ <sqlite3.Cursor object at 0x0000019BA5902AC0>

sqlite3.InterfaceError: Error binding parameter 0 - probably unsupported type.
2023-04-20 00:07:23.021 | ERROR    | __main__:<module>:22 - Error binding parameter 0 - probably unsupported type.
Traceback (most recent call last):

> File "C:\Users\zhvit\YandexDisk\telegram_bot_smm\main.py", line 20, in <module>
    launching_the_program_with_account_verification()
    └ <function launching_the_program_with_account_verification at 0x0000026D9FCE6680>

  File "C:\Users\zhvit\YandexDisk\telegram_bot_smm\main.py", line 15, in launching_the_program_with_account_verification
    main_menu()
    └ <function main_menu at 0x0000026D9FCE6320>

  File "C:\Users\zhvit\YandexDisk\telegram_bot_smm\system\menu\main_menu.py", line 61, in main_menu
    telegram_parsing_menu()
    └ <function telegram_parsing_menu at 0x0000026D9FCE6290>

  File "C:\Users\zhvit\YandexDisk\telegram_bot_smm\system\menu\main_menu.py", line 194, in telegram_parsing_menu
    parsing_of_groups_to_which_the_account_is_subscribed()
    └ <function parsing_of_groups_to_which_the_account_is_subscribed at 0x0000026D9F523520>

  File "C:\Users\zhvit\YandexDisk\telegram_bot_smm\system\actions\pars\parsing_account_groups_and_channels.py", line 28, in parsing_of_groups_to_which_the_account_is_subscribed
    writing_data_to_the_db(creating_a_table, writing_data_to_a_table, groups)
    │                      │                 │                        └ [[-1001545235329, 'Барановичский район', 'Барановичский районный исполнительный комитет', 'https://t.me/barrai'], [-100173236...
    │                      │                 └ 'INSERT INTO groups_and_channels (id, title, about, link) VALUES (?, ?, ?, ?)'
    │                      └ 'CREATE TABLE IF NOT EXISTS groups_and_channels(id, title, about, link)'
    └ <function writing_data_to_the_db at 0x0000026D9F1A2DD0>

  File "C:\Users\zhvit\YandexDisk\telegram_bot_smm\system\sqlite_working_tools\sqlite_working_tools.py", line 72, in writing_data_to_the_db
    cursor.executemany(writing_data_to_a_table, (entities,))
    │      │           │                         └ [[-1001545235329, 'Барановичский район', 'Барановичский районный исполнительный комитет', 'https://t.me/barrai'], [-100173236...
    │      │           └ 'INSERT INTO groups_and_channels (id, title, about, link) VALUES (?, ?, ?, ?)'
    │      └ <method 'executemany' of 'sqlite3.Cursor' objects>
    └ <sqlite3.Cursor object at 0x0000026D9F6B2AC0>

sqlite3.InterfaceError: Error binding parameter 0 - probably unsupported type.
2023-04-20 00:07:23.021 | ERROR    | __main__:<module>:22 - Error binding parameter 0 - probably unsupported type.
Traceback (most recent call last):

> File "C:\Users\zhvit\YandexDisk\telegram_bot_smm\main.py", line 20, in <module>
    launching_the_program_with_account_verification()
    └ <function launching_the_program_with_account_verification at 0x0000026D9FCE6680>

  File "C:\Users\zhvit\YandexDisk\telegram_bot_smm\main.py", line 15, in launching_the_program_with_account_verification
    main_menu()
    └ <function main_menu at 0x0000026D9FCE6320>

  File "C:\Users\zhvit\YandexDisk\telegram_bot_smm\system\menu\main_menu.py", line 61, in main_menu
    telegram_parsing_menu()
    └ <function telegram_parsing_menu at 0x0000026D9FCE6290>

  File "C:\Users\zhvit\YandexDisk\telegram_bot_smm\system\menu\main_menu.py", line 194, in telegram_parsing_menu
    parsing_of_groups_to_which_the_account_is_subscribed()
    └ <function parsing_of_groups_to_which_the_account_is_subscribed at 0x0000026D9F523520>

  File "C:\Users\zhvit\YandexDisk\telegram_bot_smm\system\actions\pars\parsing_account_groups_and_channels.py", line 28, in parsing_of_groups_to_which_the_account_is_subscribed
    writing_data_to_the_db(creating_a_table, writing_data_to_a_table, groups)
    │                      │                 │                        └ [[-1001545235329, 'Барановичский район', 'Барановичский районный исполнительный комитет', 'https://t.me/barrai'], [-100173236...
    │                      │                 └ 'INSERT INTO groups_and_channels (id, title, about, link) VALUES (?, ?, ?, ?)'
    │                      └ 'CREATE TABLE IF NOT EXISTS groups_and_channels(id, title, about, link)'
    └ <function writing_data_to_the_db at 0x0000026D9F1A2DD0>

  File "C:\Users\zhvit\YandexDisk\telegram_bot_smm\system\sqlite_working_tools\sqlite_working_tools.py", line 72, in writing_data_to_the_db
    cursor.executemany(writing_data_to_a_table, (entities,))
    │      │           │                         └ [[-1001545235329, 'Барановичский район', 'Барановичский районный исполнительный комитет', 'https://t.me/barrai'], [-100173236...
    │      │           └ 'INSERT INTO groups_and_channels (id, title, about, link) VALUES (?, ?, ?, ?)'
    │      └ <method 'executemany' of 'sqlite3.Cursor' objects>
    └ <sqlite3.Cursor object at 0x0000026D9F6B2AC0>

sqlite3.InterfaceError: Error binding parameter 0 - probably unsupported type.
2023-04-20 00:23:52.627 | ERROR    | __main__:<module>:22 - Error binding parameter 0 - probably unsupported type.
Traceback (most recent call last):

> File "C:\Users\zhvit\YandexDisk\telegram_bot_smm\main.py", line 20, in <module>
    launching_the_program_with_account_verification()
    └ <function launching_the_program_with_account_verification at 0x0000025E98B267A0>

  File "C:\Users\zhvit\YandexDisk\telegram_bot_smm\main.py", line 15, in launching_the_program_with_account_verification
    main_menu()
    └ <function main_menu at 0x0000025E98B26440>

  File "C:\Users\zhvit\YandexDisk\telegram_bot_smm\system\menu\main_menu.py", line 61, in main_menu
    telegram_parsing_menu()
    └ <function telegram_parsing_menu at 0x0000025E98B263B0>

  File "C:\Users\zhvit\YandexDisk\telegram_bot_smm\system\menu\main_menu.py", line 194, in telegram_parsing_menu
    parsing_of_groups_to_which_the_account_is_subscribed()
    └ <function parsing_of_groups_to_which_the_account_is_subscribed at 0x0000025E9834F5B0>

  File "C:\Users\zhvit\YandexDisk\telegram_bot_smm\system\actions\pars\parsing_account_groups_and_channels.py", line 28, in parsing_of_groups_to_which_the_account_is_subscribed
    writing_data_to_the_db(creating_a_table, writing_data_to_a_table, groups)
    │                      │                 │                        └ [[-1001545235329, 'Барановичский район', 'Барановичский районный исполнительный комитет', 'https://t.me/barrai'], [-100173236...
    │                      │                 └ 'INSERT INTO groups_and_channels (id, title, about, link) VALUES (?, ?, ?, ?)'
    │                      └ 'CREATE TABLE IF NOT EXISTS groups_and_channels(id INTEGER, title TEXT, about TEXT, link TEXT)'
    └ <function writing_data_to_the_db at 0x0000025E97FD2DD0>

  File "C:\Users\zhvit\YandexDisk\telegram_bot_smm\system\sqlite_working_tools\sqlite_working_tools.py", line 72, in writing_data_to_the_db
    cursor.executemany(writing_data_to_a_table, (entities,))
    │      │           │                         └ [[-1001545235329, 'Барановичский район', 'Барановичский районный исполнительный комитет', 'https://t.me/barrai'], [-100173236...
    │      │           └ 'INSERT INTO groups_and_channels (id, title, about, link) VALUES (?, ?, ?, ?)'
    │      └ <method 'executemany' of 'sqlite3.Cursor' objects>
    └ <sqlite3.Cursor object at 0x0000025E984E29C0>

sqlite3.InterfaceError: Error binding parameter 0 - probably unsupported type.
2023-04-20 00:23:52.627 | ERROR    | __main__:<module>:22 - Error binding parameter 0 - probably unsupported type.
Traceback (most recent call last):

> File "C:\Users\zhvit\YandexDisk\telegram_bot_smm\main.py", line 20, in <module>
    launching_the_program_with_account_verification()
    └ <function launching_the_program_with_account_verification at 0x0000025E98B267A0>

  File "C:\Users\zhvit\YandexDisk\telegram_bot_smm\main.py", line 15, in launching_the_program_with_account_verification
    main_menu()
    └ <function main_menu at 0x0000025E98B26440>

  File "C:\Users\zhvit\YandexDisk\telegram_bot_smm\system\menu\main_menu.py", line 61, in main_menu
    telegram_parsing_menu()
    └ <function telegram_parsing_menu at 0x0000025E98B263B0>

  File "C:\Users\zhvit\YandexDisk\telegram_bot_smm\system\menu\main_menu.py", line 194, in telegram_parsing_menu
    parsing_of_groups_to_which_the_account_is_subscribed()
    └ <function parsing_of_groups_to_which_the_account_is_subscribed at 0x0000025E9834F5B0>

  File "C:\Users\zhvit\YandexDisk\telegram_bot_smm\system\actions\pars\parsing_account_groups_and_channels.py", line 28, in parsing_of_groups_to_which_the_account_is_subscribed
    writing_data_to_the_db(creating_a_table, writing_data_to_a_table, groups)
    │                      │                 │                        └ [[-1001545235329, 'Барановичский район', 'Барановичский районный исполнительный комитет', 'https://t.me/barrai'], [-100173236...
    │                      │                 └ 'INSERT INTO groups_and_channels (id, title, about, link) VALUES (?, ?, ?, ?)'
    │                      └ 'CREATE TABLE IF NOT EXISTS groups_and_channels(id INTEGER, title TEXT, about TEXT, link TEXT)'
    └ <function writing_data_to_the_db at 0x0000025E97FD2DD0>

  File "C:\Users\zhvit\YandexDisk\telegram_bot_smm\system\sqlite_working_tools\sqlite_working_tools.py", line 72, in writing_data_to_the_db
    cursor.executemany(writing_data_to_a_table, (entities,))
    │      │           │                         └ [[-1001545235329, 'Барановичский район', 'Барановичский районный исполнительный комитет', 'https://t.me/barrai'], [-100173236...
    │      │           └ 'INSERT INTO groups_and_channels (id, title, about, link) VALUES (?, ?, ?, ?)'
    │      └ <method 'executemany' of 'sqlite3.Cursor' objects>
    └ <sqlite3.Cursor object at 0x0000025E984E29C0>

sqlite3.InterfaceError: Error binding parameter 0 - probably unsupported type.
2023-04-20 00:31:04.892 | ERROR    | __main__:<module>:22 - Binding 1 has no name, but you supplied a dictionary (which has only names).
Traceback (most recent call last):

> File "C:\Users\zhvit\YandexDisk\telegram_bot_smm\main.py", line 20, in <module>
    launching_the_program_with_account_verification()
    └ <function launching_the_program_with_account_verification at 0x000001C615EA6830>

  File "C:\Users\zhvit\YandexDisk\telegram_bot_smm\main.py", line 15, in launching_the_program_with_account_verification
    main_menu()
    └ <function main_menu at 0x000001C615EA64D0>

  File "C:\Users\zhvit\YandexDisk\telegram_bot_smm\system\menu\main_menu.py", line 61, in main_menu
    telegram_parsing_menu()
    └ <function telegram_parsing_menu at 0x000001C615EA6440>

  File "C:\Users\zhvit\YandexDisk\telegram_bot_smm\system\menu\main_menu.py", line 194, in telegram_parsing_menu
    parsing_of_groups_to_which_the_account_is_subscribed()
    └ <function parsing_of_groups_to_which_the_account_is_subscribed at 0x000001C6156DF5B0>

  File "C:\Users\zhvit\YandexDisk\telegram_bot_smm\system\actions\pars\parsing_account_groups_and_channels.py", line 27, in parsing_of_groups_to_which_the_account_is_subscribed
    writing_data_to_the_db(creating_a_table, writing_data_to_a_table, groups)
    │                      │                 │                        └ {-1001545235329: {'title': 'Барановичский район', 'about': 'Барановичский районный исполнительный комитет', 'link': 'https://...
    │                      │                 └ 'INSERT INTO groups_and_channels (id, title, about, link) VALUES (?, ?, ?, ?)'
    │                      └ 'CREATE TABLE IF NOT EXISTS groups_and_channels(id INTEGER, title TEXT, about TEXT, link TEXT)'
    └ <function writing_data_to_the_db at 0x000001C615362DD0>

  File "C:\Users\zhvit\YandexDisk\telegram_bot_smm\system\sqlite_working_tools\sqlite_working_tools.py", line 72, in writing_data_to_the_db
    cursor.executemany(writing_data_to_a_table, (entities,))
    │      │           │                         └ {-1001545235329: {'title': 'Барановичский район', 'about': 'Барановичский районный исполнительный комитет', 'link': 'https://...
    │      │           └ 'INSERT INTO groups_and_channels (id, title, about, link) VALUES (?, ?, ?, ?)'
    │      └ <method 'executemany' of 'sqlite3.Cursor' objects>
    └ <sqlite3.Cursor object at 0x000001C6158729C0>

sqlite3.ProgrammingError: Binding 1 has no name, but you supplied a dictionary (which has only names).
2023-04-20 00:31:04.892 | ERROR    | __main__:<module>:22 - Binding 1 has no name, but you supplied a dictionary (which has only names).
Traceback (most recent call last):

> File "C:\Users\zhvit\YandexDisk\telegram_bot_smm\main.py", line 20, in <module>
    launching_the_program_with_account_verification()
    └ <function launching_the_program_with_account_verification at 0x000001C615EA6830>

  File "C:\Users\zhvit\YandexDisk\telegram_bot_smm\main.py", line 15, in launching_the_program_with_account_verification
    main_menu()
    └ <function main_menu at 0x000001C615EA64D0>

  File "C:\Users\zhvit\YandexDisk\telegram_bot_smm\system\menu\main_menu.py", line 61, in main_menu
    telegram_parsing_menu()
    └ <function telegram_parsing_menu at 0x000001C615EA6440>

  File "C:\Users\zhvit\YandexDisk\telegram_bot_smm\system\menu\main_menu.py", line 194, in telegram_parsing_menu
    parsing_of_groups_to_which_the_account_is_subscribed()
    └ <function parsing_of_groups_to_which_the_account_is_subscribed at 0x000001C6156DF5B0>

  File "C:\Users\zhvit\YandexDisk\telegram_bot_smm\system\actions\pars\parsing_account_groups_and_channels.py", line 27, in parsing_of_groups_to_which_the_account_is_subscribed
    writing_data_to_the_db(creating_a_table, writing_data_to_a_table, groups)
    │                      │                 │                        └ {-1001545235329: {'title': 'Барановичский район', 'about': 'Барановичский районный исполнительный комитет', 'link': 'https://...
    │                      │                 └ 'INSERT INTO groups_and_channels (id, title, about, link) VALUES (?, ?, ?, ?)'
    │                      └ 'CREATE TABLE IF NOT EXISTS groups_and_channels(id INTEGER, title TEXT, about TEXT, link TEXT)'
    └ <function writing_data_to_the_db at 0x000001C615362DD0>

  File "C:\Users\zhvit\YandexDisk\telegram_bot_smm\system\sqlite_working_tools\sqlite_working_tools.py", line 72, in writing_data_to_the_db
    cursor.executemany(writing_data_to_a_table, (entities,))
    │      │           │                         └ {-1001545235329: {'title': 'Барановичский район', 'about': 'Барановичский районный исполнительный комитет', 'link': 'https://...
    │      │           └ 'INSERT INTO groups_and_channels (id, title, about, link) VALUES (?, ?, ?, ?)'
    │      └ <method 'executemany' of 'sqlite3.Cursor' objects>
    └ <sqlite3.Cursor object at 0x000001C6158729C0>

sqlite3.ProgrammingError: Binding 1 has no name, but you supplied a dictionary (which has only names).
2023-04-20 00:34:29.789 | ERROR    | __main__:<module>:22 - Error binding parameter 0 - probably unsupported type.
Traceback (most recent call last):

> File "C:\Users\zhvit\YandexDisk\telegram_bot_smm\main.py", line 20, in <module>
    launching_the_program_with_account_verification()
    └ <function launching_the_program_with_account_verification at 0x000001F1197B6680>

  File "C:\Users\zhvit\YandexDisk\telegram_bot_smm\main.py", line 15, in launching_the_program_with_account_verification
    main_menu()
    └ <function main_menu at 0x000001F1197B6320>

  File "C:\Users\zhvit\YandexDisk\telegram_bot_smm\system\menu\main_menu.py", line 61, in main_menu
    telegram_parsing_menu()
    └ <function telegram_parsing_menu at 0x000001F1197B6290>

  File "C:\Users\zhvit\YandexDisk\telegram_bot_smm\system\menu\main_menu.py", line 194, in telegram_parsing_menu
    parsing_of_groups_to_which_the_account_is_subscribed()
    └ <function parsing_of_groups_to_which_the_account_is_subscribed at 0x000001F118FF3520>

  File "C:\Users\zhvit\YandexDisk\telegram_bot_smm\system\actions\pars\parsing_account_groups_and_channels.py", line 27, in parsing_of_groups_to_which_the_account_is_subscribed
    forming_a_list_of_groups(client)
    │                        └ <telethon.client.telegramclient.TelegramClient object at 0x000001F1191D3400>
    └ <function forming_a_list_of_groups at 0x000001F118FF35B0>

  File "C:\Users\zhvit\YandexDisk\telegram_bot_smm\system\actions\pars\parsing_account_groups_and_channels.py", line 51, in forming_a_list_of_groups
    writing_data_to_the_db(creating_a_table, writing_data_to_a_table, entities)
    │                      │                 │                        └ [[-1001545235329, 'Барановичский район', 'Барановичский районный исполнительный комитет', 'https://t.me/barrai'], [-100173236...
    │                      │                 └ 'INSERT INTO groups_and_channels (id, title, about, link) VALUES (?, ?, ?, ?)'
    │                      └ 'CREATE TABLE IF NOT EXISTS groups_and_channels(id, title, about, link)'
    └ <function writing_data_to_the_db at 0x000001F118C72DD0>

  File "C:\Users\zhvit\YandexDisk\telegram_bot_smm\system\sqlite_working_tools\sqlite_working_tools.py", line 72, in writing_data_to_the_db
    cursor.executemany(writing_data_to_a_table, (entities,))
    │      │           │                         └ [[-1001545235329, 'Барановичский район', 'Барановичский районный исполнительный комитет', 'https://t.me/barrai'], [-100173236...
    │      │           └ 'INSERT INTO groups_and_channels (id, title, about, link) VALUES (?, ?, ?, ?)'
    │      └ <method 'executemany' of 'sqlite3.Cursor' objects>
    └ <sqlite3.Cursor object at 0x000001F119182A40>

sqlite3.InterfaceError: Error binding parameter 0 - probably unsupported type.
2023-04-20 00:34:29.789 | ERROR    | __main__:<module>:22 - Error binding parameter 0 - probably unsupported type.
Traceback (most recent call last):

> File "C:\Users\zhvit\YandexDisk\telegram_bot_smm\main.py", line 20, in <module>
    launching_the_program_with_account_verification()
    └ <function launching_the_program_with_account_verification at 0x000001F1197B6680>

  File "C:\Users\zhvit\YandexDisk\telegram_bot_smm\main.py", line 15, in launching_the_program_with_account_verification
    main_menu()
    └ <function main_menu at 0x000001F1197B6320>

  File "C:\Users\zhvit\YandexDisk\telegram_bot_smm\system\menu\main_menu.py", line 61, in main_menu
    telegram_parsing_menu()
    └ <function telegram_parsing_menu at 0x000001F1197B6290>

  File "C:\Users\zhvit\YandexDisk\telegram_bot_smm\system\menu\main_menu.py", line 194, in telegram_parsing_menu
    parsing_of_groups_to_which_the_account_is_subscribed()
    └ <function parsing_of_groups_to_which_the_account_is_subscribed at 0x000001F118FF3520>

  File "C:\Users\zhvit\YandexDisk\telegram_bot_smm\system\actions\pars\parsing_account_groups_and_channels.py", line 27, in parsing_of_groups_to_which_the_account_is_subscribed
    forming_a_list_of_groups(client)
    │                        └ <telethon.client.telegramclient.TelegramClient object at 0x000001F1191D3400>
    └ <function forming_a_list_of_groups at 0x000001F118FF35B0>

  File "C:\Users\zhvit\YandexDisk\telegram_bot_smm\system\actions\pars\parsing_account_groups_and_channels.py", line 51, in forming_a_list_of_groups
    writing_data_to_the_db(creating_a_table, writing_data_to_a_table, entities)
    │                      │                 │                        └ [[-1001545235329, 'Барановичский район', 'Барановичский районный исполнительный комитет', 'https://t.me/barrai'], [-100173236...
    │                      │                 └ 'INSERT INTO groups_and_channels (id, title, about, link) VALUES (?, ?, ?, ?)'
    │                      └ 'CREATE TABLE IF NOT EXISTS groups_and_channels(id, title, about, link)'
    └ <function writing_data_to_the_db at 0x000001F118C72DD0>

  File "C:\Users\zhvit\YandexDisk\telegram_bot_smm\system\sqlite_working_tools\sqlite_working_tools.py", line 72, in writing_data_to_the_db
    cursor.executemany(writing_data_to_a_table, (entities,))
    │      │           │                         └ [[-1001545235329, 'Барановичский район', 'Барановичский районный исполнительный комитет', 'https://t.me/barrai'], [-100173236...
    │      │           └ 'INSERT INTO groups_and_channels (id, title, about, link) VALUES (?, ?, ?, ?)'
    │      └ <method 'executemany' of 'sqlite3.Cursor' objects>
    └ <sqlite3.Cursor object at 0x000001F119182A40>

sqlite3.InterfaceError: Error binding parameter 0 - probably unsupported type.
2023-05-13 21:20:25.014 | ERROR    | __main__:<module>:21 - emojize() takes from 1 to 6 positional arguments but 10 were given
Traceback (most recent call last):

> File "C:\Users\zhvit\YandexDisk\telegram_bot_smm\main.py", line 19, in <module>
    launching_the_program_with_account_verification()
    └ <function launching_the_program_with_account_verification at 0x000002B07BF371C0>

  File "C:\Users\zhvit\YandexDisk\telegram_bot_smm\main.py", line 14, in launching_the_program_with_account_verification
    main_menu()
    └ <function main_menu at 0x000002B07BF36E60>

  File "C:\Users\zhvit\YandexDisk\telegram_bot_smm\system\menu\main_menu.py", line 60, in main_menu
    working_with_the_reaction()
    └ <function working_with_the_reaction at 0x000002B07BF37010>

  File "C:\Users\zhvit\YandexDisk\telegram_bot_smm\system\menu\main_menu.py", line 261, in working_with_the_reaction
    users_choice_of_reaction()
    └ <function users_choice_of_reaction at 0x000002B07B7757E0>

  File "C:\Users\zhvit\YandexDisk\telegram_bot_smm\system\actions\reactions\reactions.py", line 33, in users_choice_of_reaction
    print(emoji.emojize("[bold green][0] Поднятый большой палец :thumbs_up:\n",
    │     │     └ <function emojize at 0x000002B07BF35000>
    │     └ <module 'emoji' from 'C:\\Users\\zhvit\\AppData\\Local\\Programs\\Python\\Python310\\lib\\site-packages\\emoji\\__init__.py'>
    └ <function print at 0x000002B07954B520>

TypeError: emojize() takes from 1 to 6 positional arguments but 10 were given
2023-05-13 21:20:25.014 | ERROR    | __main__:<module>:21 - emojize() takes from 1 to 6 positional arguments but 10 were given
Traceback (most recent call last):

> File "C:\Users\zhvit\YandexDisk\telegram_bot_smm\main.py", line 19, in <module>
    launching_the_program_with_account_verification()
    └ <function launching_the_program_with_account_verification at 0x000002B07BF371C0>

  File "C:\Users\zhvit\YandexDisk\telegram_bot_smm\main.py", line 14, in launching_the_program_with_account_verification
    main_menu()
    └ <function main_menu at 0x000002B07BF36E60>

  File "C:\Users\zhvit\YandexDisk\telegram_bot_smm\system\menu\main_menu.py", line 60, in main_menu
    working_with_the_reaction()
    └ <function working_with_the_reaction at 0x000002B07BF37010>

  File "C:\Users\zhvit\YandexDisk\telegram_bot_smm\system\menu\main_menu.py", line 261, in working_with_the_reaction
    users_choice_of_reaction()
    └ <function users_choice_of_reaction at 0x000002B07B7757E0>

  File "C:\Users\zhvit\YandexDisk\telegram_bot_smm\system\actions\reactions\reactions.py", line 33, in users_choice_of_reaction
    print(emoji.emojize("[bold green][0] Поднятый большой палец :thumbs_up:\n",
    │     │     └ <function emojize at 0x000002B07BF35000>
    │     └ <module 'emoji' from 'C:\\Users\\zhvit\\AppData\\Local\\Programs\\Python\\Python310\\lib\\site-packages\\emoji\\__init__.py'>
    └ <function print at 0x000002B07954B520>

TypeError: emojize() takes from 1 to 6 positional arguments but 10 were given
2023-05-13 21:23:24.989 | ERROR    | __main__:<module>:21 - emojize() takes from 1 to 6 positional arguments but 10 were given
Traceback (most recent call last):

> File "C:\Users\zhvit\YandexDisk\telegram_bot_smm\main.py", line 19, in <module>
    launching_the_program_with_account_verification()
    └ <function launching_the_program_with_account_verification at 0x0000029C04503250>

  File "C:\Users\zhvit\YandexDisk\telegram_bot_smm\main.py", line 14, in launching_the_program_with_account_verification
    main_menu()
    └ <function main_menu at 0x0000029C04502EF0>

  File "C:\Users\zhvit\YandexDisk\telegram_bot_smm\system\menu\main_menu.py", line 60, in main_menu
    working_with_the_reaction()
    └ <function working_with_the_reaction at 0x0000029C045030A0>

  File "C:\Users\zhvit\YandexDisk\telegram_bot_smm\system\menu\main_menu.py", line 261, in working_with_the_reaction
    users_choice_of_reaction()
    └ <function users_choice_of_reaction at 0x0000029C03D49AB0>

  File "C:\Users\zhvit\YandexDisk\telegram_bot_smm\system\actions\reactions\reactions.py", line 33, in users_choice_of_reaction
    print(emoji.emojize("[bold green][0] Поднятый большой палец :thumbs_up:\n",
    │     │     └ <function emojize at 0x0000029C04501090>
    │     └ <module 'emoji' from 'C:\\Users\\zhvit\\AppData\\Local\\Programs\\Python\\Python310\\lib\\site-packages\\emoji\\__init__.py'>
    └ <function print at 0x0000029C01B1B490>

TypeError: emojize() takes from 1 to 6 positional arguments but 10 were given
2023-05-13 21:23:24.989 | ERROR    | __main__:<module>:21 - emojize() takes from 1 to 6 positional arguments but 10 were given
Traceback (most recent call last):

> File "C:\Users\zhvit\YandexDisk\telegram_bot_smm\main.py", line 19, in <module>
    launching_the_program_with_account_verification()
    └ <function launching_the_program_with_account_verification at 0x0000029C04503250>

  File "C:\Users\zhvit\YandexDisk\telegram_bot_smm\main.py", line 14, in launching_the_program_with_account_verification
    main_menu()
    └ <function main_menu at 0x0000029C04502EF0>

  File "C:\Users\zhvit\YandexDisk\telegram_bot_smm\system\menu\main_menu.py", line 60, in main_menu
    working_with_the_reaction()
    └ <function working_with_the_reaction at 0x0000029C045030A0>

  File "C:\Users\zhvit\YandexDisk\telegram_bot_smm\system\menu\main_menu.py", line 261, in working_with_the_reaction
    users_choice_of_reaction()
    └ <function users_choice_of_reaction at 0x0000029C03D49AB0>

  File "C:\Users\zhvit\YandexDisk\telegram_bot_smm\system\actions\reactions\reactions.py", line 33, in users_choice_of_reaction
    print(emoji.emojize("[bold green][0] Поднятый большой палец :thumbs_up:\n",
    │     │     └ <function emojize at 0x0000029C04501090>
    │     └ <module 'emoji' from 'C:\\Users\\zhvit\\AppData\\Local\\Programs\\Python\\Python310\\lib\\site-packages\\emoji\\__init__.py'>
    └ <function print at 0x0000029C01B1B490>

TypeError: emojize() takes from 1 to 6 positional arguments but 10 were given
