2023-09-18 00:14:32.199 | ERROR    | __main__:<module>:22 - 'charmap' codec can't encode characters in position 0-6: character maps to <undefined>
Traceback (most recent call last):

> File "C:\Users\zhvit\YandexDisk\Python\telegram_bot_smm\main.py", line 20, in <module>
    launching_the_program_with_account_verification()
    └ <function launching_the_program_with_account_verification at 0x0000021CD6FB4AF0>

  File "C:\Users\zhvit\YandexDisk\Python\telegram_bot_smm\main.py", line 15, in launching_the_program_with_account_verification
    main_menu()  # Основное меню программы
    └ <function main_menu at 0x0000021CD6FB4670>

  File "C:\Users\zhvit\YandexDisk\Python\telegram_bot_smm\system\menu\main_menu_interface.py", line 26, in main_menu
    clearing_console_showing_banner()  # Чистим консоль, выводим банер
    └ <function clearing_console_showing_banner at 0x0000021CD6F86A70>

  File "C:\Users\zhvit\YandexDisk\Python\telegram_bot_smm\system\auxiliary_functions\auxiliary_functions.py", line 56, in clearing_console_showing_banner
    banner()  # Ставим банер программы, для красивого визуального отображения
    └ <function banner at 0x0000021CD6EF6830>

  File "C:\Users\zhvit\YandexDisk\Python\telegram_bot_smm\system\menu\app_banner.py", line 9, in banner
    console.print("╔╦╗╔═╗╦  ╔═╗╔═╗╦═╗╔═╗╔╦╗    ╔═╗╔╦╗╔╦╗    ╔╗ ╔═╗╔╦╗", style="bold red", justify="center")
    │       └ <function Console.print at 0x0000021CD6EF44C0>
    └ <console width=79 None>

  File "C:\Users\zhvit\AppData\Local\Programs\Python\Python310\lib\site-packages\rich\console.py", line 1646, in print
    with self:
         └ <console width=79 None>

  File "C:\Users\zhvit\AppData\Local\Programs\Python\Python310\lib\site-packages\rich\console.py", line 848, in __exit__
    self._exit_buffer()
    │    └ <function Console._exit_buffer at 0x0000021CD6EDEA70>
    └ <console width=79 None>

  File "C:\Users\zhvit\AppData\Local\Programs\Python\Python310\lib\site-packages\rich\console.py", line 806, in _exit_buffer
    self._check_buffer()
    │    └ <function Console._check_buffer at 0x0000021CD6EF48B0>
    └ <console width=79 None>

  File "C:\Users\zhvit\AppData\Local\Programs\Python\Python310\lib\site-packages\rich\console.py", line 1999, in _check_buffer
    legacy_windows_render(
    └ <function legacy_windows_render at 0x0000021CD6FB4DC0>

  File "C:\Users\zhvit\AppData\Local\Programs\Python\Python310\lib\site-packages\rich\_windows_renderer.py", line 17, in legacy_windows_render
    term.write_styled(text, style)
    │    │            │     └ Style(color=Color('red', ColorType.STANDARD, number=1), bold=True)
    │    │            └ '╔╦╗╔═╗╦  ╔═╗╔═╗╦═╗╔═╗╔╦╗    ╔═╗╔╦╗╔╦╗    ╔╗ ╔═╗╔╦╗'
    │    └ <function LegacyWindowsTerm.write_styled at 0x0000021CD6EF5F30>
    └ <rich._win32_console.LegacyWindowsTerm object at 0x0000021CD6F8A650>

  File "C:\Users\zhvit\AppData\Local\Programs\Python\Python310\lib\site-packages\rich\_win32_console.py", line 442, in write_styled
    self.write_text(text)
    │    │          └ '╔╦╗╔═╗╦  ╔═╗╔═╗╦═╗╔═╗╔╦╗    ╔═╗╔╦╗╔╦╗    ╔╗ ╔═╗╔╦╗'
    │    └ <function LegacyWindowsTerm.write_text at 0x0000021CD6EF5EA0>
    └ <rich._win32_console.LegacyWindowsTerm object at 0x0000021CD6F8A650>

  File "C:\Users\zhvit\AppData\Local\Programs\Python\Python310\lib\site-packages\rich\_win32_console.py", line 403, in write_text
    self.write(text)
    │    │     └ '╔╦╗╔═╗╦  ╔═╗╔═╗╦═╗╔═╗╔╦╗    ╔═╗╔╦╗╔╦╗    ╔╗ ╔═╗╔╦╗'
    │    └ <built-in method write of _io.TextIOWrapper object at 0x0000021CD27D1150>
    └ <rich._win32_console.LegacyWindowsTerm object at 0x0000021CD6F8A650>

  File "C:\Users\zhvit\AppData\Local\Programs\Python\Python310\lib\encodings\cp1251.py", line 19, in encode
    return codecs.charmap_encode(input,self.errors,encoding_table)[0]
           │      │              │     │    │      └ <EncodingMap object at 0x0000021CD2239E80>
           │      │              │     │    └ 'strict'
           │      │              │     └ <encodings.cp1251.IncrementalEncoder object at 0x0000021CD2888820>
           │      │              └ '╔╦╗╔═╗╦  ╔═╗╔═╗╦═╗╔═╗╔╦╗    ╔═╗╔╦╗╔╦╗    ╔╗ ╔═╗╔╦╗'
           │      └ <built-in function charmap_encode>
           └ <module 'codecs' from 'C:\\Users\\zhvit\\AppData\\Local\\Programs\\Python\\Python310\\lib\\codecs.py'>

UnicodeEncodeError: 'charmap' codec can't encode characters in position 0-6: character maps to <undefined>
2023-09-18 00:18:08.053 | ERROR    | __main__:<module>:22 - 'charmap' codec can't encode characters in position 0-6: character maps to <undefined>
Traceback (most recent call last):

> File "C:\Users\zhvit\YandexDisk\Python\telegram_bot_smm\main.py", line 20, in <module>
    launching_the_program_with_account_verification()
    └ <function launching_the_program_with_account_verification at 0x000001EC7A8B8A60>

  File "C:\Users\zhvit\YandexDisk\Python\telegram_bot_smm\main.py", line 15, in launching_the_program_with_account_verification
    main_menu()  # Основное меню программы
    └ <function main_menu at 0x000001EC7A8B85E0>

  File "C:\Users\zhvit\YandexDisk\Python\telegram_bot_smm\system\menu\main_menu_interface.py", line 26, in main_menu
    clearing_console_showing_banner()  # Чистим консоль, выводим банер
    └ <function clearing_console_showing_banner at 0x000001EC7A88A9E0>

  File "C:\Users\zhvit\YandexDisk\Python\telegram_bot_smm\system\auxiliary_functions\auxiliary_functions.py", line 56, in clearing_console_showing_banner
    banner()  # Ставим банер программы, для красивого визуального отображения
    └ <function banner at 0x000001EC7A7F27A0>

  File "C:\Users\zhvit\YandexDisk\Python\telegram_bot_smm\system\menu\app_banner.py", line 9, in banner
    console.print("╔╦╗╔═╗╦  ╔═╗╔═╗╦═╗╔═╗╔╦╗    ╔═╗╔╦╗╔╦╗    ╔╗ ╔═╗╔╦╗", style="bold red", justify="center")
    │       └ <function Console.print at 0x000001EC7A7F0430>
    └ <console width=79 None>

  File "C:\Users\zhvit\AppData\Local\Programs\Python\Python310\lib\site-packages\rich\console.py", line 1646, in print
    with self:
         └ <console width=79 None>

  File "C:\Users\zhvit\AppData\Local\Programs\Python\Python310\lib\site-packages\rich\console.py", line 848, in __exit__
    self._exit_buffer()
    │    └ <function Console._exit_buffer at 0x000001EC7A7DA9E0>
    └ <console width=79 None>

  File "C:\Users\zhvit\AppData\Local\Programs\Python\Python310\lib\site-packages\rich\console.py", line 806, in _exit_buffer
    self._check_buffer()
    │    └ <function Console._check_buffer at 0x000001EC7A7F0820>
    └ <console width=79 None>

  File "C:\Users\zhvit\AppData\Local\Programs\Python\Python310\lib\site-packages\rich\console.py", line 1999, in _check_buffer
    legacy_windows_render(
    └ <function legacy_windows_render at 0x000001EC7A8B8D30>

  File "C:\Users\zhvit\AppData\Local\Programs\Python\Python310\lib\site-packages\rich\_windows_renderer.py", line 17, in legacy_windows_render
    term.write_styled(text, style)
    │    │            │     └ Style(color=Color('red', ColorType.STANDARD, number=1), bold=True)
    │    │            └ '╔╦╗╔═╗╦  ╔═╗╔═╗╦═╗╔═╗╔╦╗    ╔═╗╔╦╗╔╦╗    ╔╗ ╔═╗╔╦╗'
    │    └ <function LegacyWindowsTerm.write_styled at 0x000001EC7A7F1EA0>
    └ <rich._win32_console.LegacyWindowsTerm object at 0x000001EC7A8968F0>

  File "C:\Users\zhvit\AppData\Local\Programs\Python\Python310\lib\site-packages\rich\_win32_console.py", line 442, in write_styled
    self.write_text(text)
    │    │          └ '╔╦╗╔═╗╦  ╔═╗╔═╗╦═╗╔═╗╔╦╗    ╔═╗╔╦╗╔╦╗    ╔╗ ╔═╗╔╦╗'
    │    └ <function LegacyWindowsTerm.write_text at 0x000001EC7A7F1E10>
    └ <rich._win32_console.LegacyWindowsTerm object at 0x000001EC7A8968F0>

  File "C:\Users\zhvit\AppData\Local\Programs\Python\Python310\lib\site-packages\rich\_win32_console.py", line 403, in write_text
    self.write(text)
    │    │     └ '╔╦╗╔═╗╦  ╔═╗╔═╗╦═╗╔═╗╔╦╗    ╔═╗╔╦╗╔╦╗    ╔╗ ╔═╗╔╦╗'
    │    └ <built-in method write of _io.TextIOWrapper object at 0x000001EC760D1150>
    └ <rich._win32_console.LegacyWindowsTerm object at 0x000001EC7A8968F0>

  File "C:\Users\zhvit\AppData\Local\Programs\Python\Python310\lib\encodings\cp1251.py", line 19, in encode
    return codecs.charmap_encode(input,self.errors,encoding_table)[0]
           │      │              │     │    │      └ <EncodingMap object at 0x000001EC75BFBAD0>
           │      │              │     │    └ 'strict'
           │      │              │     └ <encodings.cp1251.IncrementalEncoder object at 0x000001EC76188820>
           │      │              └ '╔╦╗╔═╗╦  ╔═╗╔═╗╦═╗╔═╗╔╦╗    ╔═╗╔╦╗╔╦╗    ╔╗ ╔═╗╔╦╗'
           │      └ <built-in function charmap_encode>
           └ <module 'codecs' from 'C:\\Users\\zhvit\\AppData\\Local\\Programs\\Python\\Python310\\lib\\codecs.py'>

UnicodeEncodeError: 'charmap' codec can't encode characters in position 0-6: character maps to <undefined>
2023-09-18 00:18:08.053 | ERROR    | __main__:<module>:22 - 'charmap' codec can't encode characters in position 0-6: character maps to <undefined>
Traceback (most recent call last):

> File "C:\Users\zhvit\YandexDisk\Python\telegram_bot_smm\main.py", line 20, in <module>
    launching_the_program_with_account_verification()
    └ <function launching_the_program_with_account_verification at 0x000001EC7A8B8A60>

  File "C:\Users\zhvit\YandexDisk\Python\telegram_bot_smm\main.py", line 15, in launching_the_program_with_account_verification
    main_menu()  # Основное меню программы
    └ <function main_menu at 0x000001EC7A8B85E0>

  File "C:\Users\zhvit\YandexDisk\Python\telegram_bot_smm\system\menu\main_menu_interface.py", line 26, in main_menu
    clearing_console_showing_banner()  # Чистим консоль, выводим банер
    └ <function clearing_console_showing_banner at 0x000001EC7A88A9E0>

  File "C:\Users\zhvit\YandexDisk\Python\telegram_bot_smm\system\auxiliary_functions\auxiliary_functions.py", line 56, in clearing_console_showing_banner
    banner()  # Ставим банер программы, для красивого визуального отображения
    └ <function banner at 0x000001EC7A7F27A0>

  File "C:\Users\zhvit\YandexDisk\Python\telegram_bot_smm\system\menu\app_banner.py", line 9, in banner
    console.print("╔╦╗╔═╗╦  ╔═╗╔═╗╦═╗╔═╗╔╦╗    ╔═╗╔╦╗╔╦╗    ╔╗ ╔═╗╔╦╗", style="bold red", justify="center")
    │       └ <function Console.print at 0x000001EC7A7F0430>
    └ <console width=79 None>

  File "C:\Users\zhvit\AppData\Local\Programs\Python\Python310\lib\site-packages\rich\console.py", line 1646, in print
    with self:
         └ <console width=79 None>

  File "C:\Users\zhvit\AppData\Local\Programs\Python\Python310\lib\site-packages\rich\console.py", line 848, in __exit__
    self._exit_buffer()
    │    └ <function Console._exit_buffer at 0x000001EC7A7DA9E0>
    └ <console width=79 None>

  File "C:\Users\zhvit\AppData\Local\Programs\Python\Python310\lib\site-packages\rich\console.py", line 806, in _exit_buffer
    self._check_buffer()
    │    └ <function Console._check_buffer at 0x000001EC7A7F0820>
    └ <console width=79 None>

  File "C:\Users\zhvit\AppData\Local\Programs\Python\Python310\lib\site-packages\rich\console.py", line 1999, in _check_buffer
    legacy_windows_render(
    └ <function legacy_windows_render at 0x000001EC7A8B8D30>

  File "C:\Users\zhvit\AppData\Local\Programs\Python\Python310\lib\site-packages\rich\_windows_renderer.py", line 17, in legacy_windows_render
    term.write_styled(text, style)
    │    │            │     └ Style(color=Color('red', ColorType.STANDARD, number=1), bold=True)
    │    │            └ '╔╦╗╔═╗╦  ╔═╗╔═╗╦═╗╔═╗╔╦╗    ╔═╗╔╦╗╔╦╗    ╔╗ ╔═╗╔╦╗'
    │    └ <function LegacyWindowsTerm.write_styled at 0x000001EC7A7F1EA0>
    └ <rich._win32_console.LegacyWindowsTerm object at 0x000001EC7A8968F0>

  File "C:\Users\zhvit\AppData\Local\Programs\Python\Python310\lib\site-packages\rich\_win32_console.py", line 442, in write_styled
    self.write_text(text)
    │    │          └ '╔╦╗╔═╗╦  ╔═╗╔═╗╦═╗╔═╗╔╦╗    ╔═╗╔╦╗╔╦╗    ╔╗ ╔═╗╔╦╗'
    │    └ <function LegacyWindowsTerm.write_text at 0x000001EC7A7F1E10>
    └ <rich._win32_console.LegacyWindowsTerm object at 0x000001EC7A8968F0>

  File "C:\Users\zhvit\AppData\Local\Programs\Python\Python310\lib\site-packages\rich\_win32_console.py", line 403, in write_text
    self.write(text)
    │    │     └ '╔╦╗╔═╗╦  ╔═╗╔═╗╦═╗╔═╗╔╦╗    ╔═╗╔╦╗╔╦╗    ╔╗ ╔═╗╔╦╗'
    │    └ <built-in method write of _io.TextIOWrapper object at 0x000001EC760D1150>
    └ <rich._win32_console.LegacyWindowsTerm object at 0x000001EC7A8968F0>

  File "C:\Users\zhvit\AppData\Local\Programs\Python\Python310\lib\encodings\cp1251.py", line 19, in encode
    return codecs.charmap_encode(input,self.errors,encoding_table)[0]
           │      │              │     │    │      └ <EncodingMap object at 0x000001EC75BFBAD0>
           │      │              │     │    └ 'strict'
           │      │              │     └ <encodings.cp1251.IncrementalEncoder object at 0x000001EC76188820>
           │      │              └ '╔╦╗╔═╗╦  ╔═╗╔═╗╦═╗╔═╗╔╦╗    ╔═╗╔╦╗╔╦╗    ╔╗ ╔═╗╔╦╗'
           │      └ <built-in function charmap_encode>
           └ <module 'codecs' from 'C:\\Users\\zhvit\\AppData\\Local\\Programs\\Python\\Python310\\lib\\codecs.py'>

UnicodeEncodeError: 'charmap' codec can't encode characters in position 0-6: character maps to <undefined>
2023-11-01 16:51:38.702 | ERROR    | __main__:<module>:20 - DatabaseHandler.cleaning_db() missing 1 required positional argument: 'self'
Traceback (most recent call last):

> File "C:\Users\zhvit\YandexDisk\Python\telegram_bot_smm\main.py", line 18, in <module>
    launching_the_program_with_account_verification()
    └ <function launching_the_program_with_account_verification at 0x000001C34B06E0C0>

  File "C:\Users\zhvit\YandexDisk\Python\telegram_bot_smm\main.py", line 12, in launching_the_program_with_account_verification
    deleting_files_by_dictionary()
    └ <function deleting_files_by_dictionary at 0x000001C34B062AC0>

  File "C:\Users\zhvit\YandexDisk\Python\telegram_bot_smm\system\telegram_actions\account_verification.py", line 24, in deleting_files_by_dictionary
    writing_names_found_files_to_the_db()  # Сканируем папку с аккаунтами на наличие сессий
    └ <function writing_names_found_files_to_the_db at 0x000001C34AFE7740>

  File "C:\Users\zhvit\YandexDisk\Python\telegram_bot_smm\system\telegram_actions\telegram_actions.py", line 59, in writing_names_found_files_to_the_db
    db_handler.cleaning_db(name_database_table="config")  # Чистим базу данных с аккаунтами
    │          └ <function DatabaseHandler.cleaning_db at 0x000001C34994FC40>
    └ <class 'system.sqlite_working_tools.sqlite_working_tools.DatabaseHandler'>

TypeError: DatabaseHandler.cleaning_db() missing 1 required positional argument: 'self'
2023-11-01 16:51:38.702 | ERROR    | __main__:<module>:20 - DatabaseHandler.cleaning_db() missing 1 required positional argument: 'self'
Traceback (most recent call last):

> File "C:\Users\zhvit\YandexDisk\Python\telegram_bot_smm\main.py", line 18, in <module>
    launching_the_program_with_account_verification()
    └ <function launching_the_program_with_account_verification at 0x000001C34B06E0C0>

  File "C:\Users\zhvit\YandexDisk\Python\telegram_bot_smm\main.py", line 12, in launching_the_program_with_account_verification
    deleting_files_by_dictionary()
    └ <function deleting_files_by_dictionary at 0x000001C34B062AC0>

  File "C:\Users\zhvit\YandexDisk\Python\telegram_bot_smm\system\telegram_actions\account_verification.py", line 24, in deleting_files_by_dictionary
    writing_names_found_files_to_the_db()  # Сканируем папку с аккаунтами на наличие сессий
    └ <function writing_names_found_files_to_the_db at 0x000001C34AFE7740>

  File "C:\Users\zhvit\YandexDisk\Python\telegram_bot_smm\system\telegram_actions\telegram_actions.py", line 59, in writing_names_found_files_to_the_db
    db_handler.cleaning_db(name_database_table="config")  # Чистим базу данных с аккаунтами
    │          └ <function DatabaseHandler.cleaning_db at 0x000001C34994FC40>
    └ <class 'system.sqlite_working_tools.sqlite_working_tools.DatabaseHandler'>

TypeError: DatabaseHandler.cleaning_db() missing 1 required positional argument: 'self'
2023-11-01 16:52:19.406 | ERROR    | __main__:<module>:20 - DatabaseHandler.cleaning_db() missing 1 required positional argument: 'self'
Traceback (most recent call last):

> File "C:\Users\zhvit\YandexDisk\Python\telegram_bot_smm\main.py", line 18, in <module>
    launching_the_program_with_account_verification()
    └ <function launching_the_program_with_account_verification at 0x0000022E8E792520>

  File "C:\Users\zhvit\YandexDisk\Python\telegram_bot_smm\main.py", line 12, in launching_the_program_with_account_verification
    deleting_files_by_dictionary()
    └ <function deleting_files_by_dictionary at 0x0000022E8E77EE80>

  File "C:\Users\zhvit\YandexDisk\Python\telegram_bot_smm\system\telegram_actions\account_verification.py", line 24, in deleting_files_by_dictionary
    writing_names_found_files_to_the_db()  # Сканируем папку с аккаунтами на наличие сессий
    └ <function writing_names_found_files_to_the_db at 0x0000022E8E6FB6A0>

  File "C:\Users\zhvit\YandexDisk\Python\telegram_bot_smm\system\telegram_actions\telegram_actions.py", line 59, in writing_names_found_files_to_the_db
    db_handler.cleaning_db(name_database_table="config")  # Чистим базу данных с аккаунтами
    │          └ <function DatabaseHandler.cleaning_db at 0x0000022E8D06FBA0>
    └ <class 'system.sqlite_working_tools.sqlite_working_tools.DatabaseHandler'>

TypeError: DatabaseHandler.cleaning_db() missing 1 required positional argument: 'self'
2023-11-01 16:52:19.406 | ERROR    | __main__:<module>:20 - DatabaseHandler.cleaning_db() missing 1 required positional argument: 'self'
Traceback (most recent call last):

> File "C:\Users\zhvit\YandexDisk\Python\telegram_bot_smm\main.py", line 18, in <module>
    launching_the_program_with_account_verification()
    └ <function launching_the_program_with_account_verification at 0x0000022E8E792520>

  File "C:\Users\zhvit\YandexDisk\Python\telegram_bot_smm\main.py", line 12, in launching_the_program_with_account_verification
    deleting_files_by_dictionary()
    └ <function deleting_files_by_dictionary at 0x0000022E8E77EE80>

  File "C:\Users\zhvit\YandexDisk\Python\telegram_bot_smm\system\telegram_actions\account_verification.py", line 24, in deleting_files_by_dictionary
    writing_names_found_files_to_the_db()  # Сканируем папку с аккаунтами на наличие сессий
    └ <function writing_names_found_files_to_the_db at 0x0000022E8E6FB6A0>

  File "C:\Users\zhvit\YandexDisk\Python\telegram_bot_smm\system\telegram_actions\telegram_actions.py", line 59, in writing_names_found_files_to_the_db
    db_handler.cleaning_db(name_database_table="config")  # Чистим базу данных с аккаунтами
    │          └ <function DatabaseHandler.cleaning_db at 0x0000022E8D06FBA0>
    └ <class 'system.sqlite_working_tools.sqlite_working_tools.DatabaseHandler'>

TypeError: DatabaseHandler.cleaning_db() missing 1 required positional argument: 'self'
2023-11-01 16:59:20.751 | ERROR    | __main__:<module>:20 - incomplete input
Traceback (most recent call last):

> File "C:\Users\zhvit\YandexDisk\Python\telegram_bot_smm\main.py", line 18, in <module>
    launching_the_program_with_account_verification()
    └ <function launching_the_program_with_account_verification at 0x000001C694F92520>

  File "C:\Users\zhvit\YandexDisk\Python\telegram_bot_smm\main.py", line 12, in launching_the_program_with_account_verification
    deleting_files_by_dictionary()
    └ <function deleting_files_by_dictionary at 0x000001C694F7EE80>

  File "C:\Users\zhvit\YandexDisk\Python\telegram_bot_smm\system\telegram_actions\account_verification.py", line 24, in deleting_files_by_dictionary
    writing_names_found_files_to_the_db()  # Сканируем папку с аккаунтами на наличие сессий
    └ <function writing_names_found_files_to_the_db at 0x000001C694EFB6A0>

  File "C:\Users\zhvit\YandexDisk\Python\telegram_bot_smm\system\telegram_actions\telegram_actions.py", line 63, in writing_names_found_files_to_the_db
    db_handler.write_data_to_db(creating_a_table, writing_data_to_a_table, entities)
    │          │                │                 │                        └ ['7655060', 'cc1290cd733c1f1d407598e5a31be4a8', '79112613851']
    │          │                │                 └ 'INSERT INTO config (id, hash, phone) VALUES (?, ?, ?'
    │          │                └ 'CREATE TABLE IF NOT EXISTS config(id, hash, phone)'
    │          └ <function DatabaseHandler.write_data_to_db at 0x000001C69387F6A0>
    └ <system.sqlite_working_tools.sqlite_working_tools.DatabaseHandler object at 0x000001C694F05290>

  File "C:\Users\zhvit\YandexDisk\Python\telegram_bot_smm\system\sqlite_working_tools\sqlite_working_tools.py", line 55, in write_data_to_db
    self.cursor.executemany(writing_data_to_a_table, (entities,))
    │    │      │           │                         └ ['7655060', 'cc1290cd733c1f1d407598e5a31be4a8', '79112613851']
    │    │      │           └ 'INSERT INTO config (id, hash, phone) VALUES (?, ?, ?'
    │    │      └ <method 'executemany' of 'sqlite3.Cursor' objects>
    │    └ <sqlite3.Cursor object at 0x000001C694FA18C0>
    └ <system.sqlite_working_tools.sqlite_working_tools.DatabaseHandler object at 0x000001C694F05290>

sqlite3.OperationalError: incomplete input
2023-11-01 16:59:20.751 | ERROR    | __main__:<module>:20 - incomplete input
Traceback (most recent call last):

> File "C:\Users\zhvit\YandexDisk\Python\telegram_bot_smm\main.py", line 18, in <module>
    launching_the_program_with_account_verification()
    └ <function launching_the_program_with_account_verification at 0x000001C694F92520>

  File "C:\Users\zhvit\YandexDisk\Python\telegram_bot_smm\main.py", line 12, in launching_the_program_with_account_verification
    deleting_files_by_dictionary()
    └ <function deleting_files_by_dictionary at 0x000001C694F7EE80>

  File "C:\Users\zhvit\YandexDisk\Python\telegram_bot_smm\system\telegram_actions\account_verification.py", line 24, in deleting_files_by_dictionary
    writing_names_found_files_to_the_db()  # Сканируем папку с аккаунтами на наличие сессий
    └ <function writing_names_found_files_to_the_db at 0x000001C694EFB6A0>

  File "C:\Users\zhvit\YandexDisk\Python\telegram_bot_smm\system\telegram_actions\telegram_actions.py", line 63, in writing_names_found_files_to_the_db
    db_handler.write_data_to_db(creating_a_table, writing_data_to_a_table, entities)
    │          │                │                 │                        └ ['7655060', 'cc1290cd733c1f1d407598e5a31be4a8', '79112613851']
    │          │                │                 └ 'INSERT INTO config (id, hash, phone) VALUES (?, ?, ?'
    │          │                └ 'CREATE TABLE IF NOT EXISTS config(id, hash, phone)'
    │          └ <function DatabaseHandler.write_data_to_db at 0x000001C69387F6A0>
    └ <system.sqlite_working_tools.sqlite_working_tools.DatabaseHandler object at 0x000001C694F05290>

  File "C:\Users\zhvit\YandexDisk\Python\telegram_bot_smm\system\sqlite_working_tools\sqlite_working_tools.py", line 55, in write_data_to_db
    self.cursor.executemany(writing_data_to_a_table, (entities,))
    │    │      │           │                         └ ['7655060', 'cc1290cd733c1f1d407598e5a31be4a8', '79112613851']
    │    │      │           └ 'INSERT INTO config (id, hash, phone) VALUES (?, ?, ?'
    │    │      └ <method 'executemany' of 'sqlite3.Cursor' objects>
    │    └ <sqlite3.Cursor object at 0x000001C694FA18C0>
    └ <system.sqlite_working_tools.sqlite_working_tools.DatabaseHandler object at 0x000001C694F05290>

sqlite3.OperationalError: incomplete input
2023-11-07 10:38:23.445 | ERROR    | __main__:<module>:20 - 'UserStatusOnline' object is not callable
Traceback (most recent call last):

> File "C:\Users\zhvit\YandexDisk\Python\telegram_bot_smm\main.py", line 18, in <module>
    launching_the_program_with_account_verification()
    └ <function launching_the_program_with_account_verification at 0x0000025715F12520>

  File "C:\Users\zhvit\YandexDisk\Python\telegram_bot_smm\main.py", line 13, in launching_the_program_with_account_verification
    main_menu()  # Основное меню программы
    └ <function main_menu at 0x00000257106BE480>

  File "C:\Users\zhvit\YandexDisk\Python\telegram_bot_smm\system\menu\main_menu_interface.py", line 43, in main_menu
    telegram_parsing_menu()
    └ <function telegram_parsing_menu at 0x0000025715F12660>

  File "C:\Users\zhvit\YandexDisk\Python\telegram_bot_smm\system\menu\main_menu_interface.py", line 143, in telegram_parsing_menu
    main_menu()  # После отработки функции переходим в начальное меню
    └ <function main_menu at 0x00000257106BE480>

  File "C:\Users\zhvit\YandexDisk\Python\telegram_bot_smm\system\menu\main_menu_interface.py", line 43, in main_menu
    telegram_parsing_menu()
    └ <function telegram_parsing_menu at 0x0000025715F12660>

  File "C:\Users\zhvit\YandexDisk\Python\telegram_bot_smm\system\menu\main_menu_interface.py", line 117, in telegram_parsing_menu
    parsing_mass_parsing_of_groups()  # Парсинг участников чата
    └ <function parsing_mass_parsing_of_groups at 0x0000025715EFFBA0>

  File "C:\Users\zhvit\YandexDisk\Python\telegram_bot_smm\system\actions\pars\parsing_group_members.py", line 69, in parsing_mass_parsing_of_groups
    group_parsing(client, groups_wr, phone)  # Parsing групп
    │             │       │          └ '375297929184'
    │             │       └ 'https://t.me/gk_levada'
    │             └ <telethon.client.telegramclient.TelegramClient object at 0x0000025715F567D0>
    └ <function handle_exceptions_pars.<locals>.wrapper at 0x0000025715EFFCE0>

  File "C:\Users\zhvit\YandexDisk\Python\telegram_bot_smm\system\error\telegram_errors.py", line 56, in wrapper
    return func(*args, **kwargs)
           │     │       └ {}
           │     └ (<telethon.client.telegramclient.TelegramClient object at 0x0000025715F567D0>, 'https://t.me/gk_levada', '375297929184')
           └ <function group_parsing at 0x0000025715EFFC40>

  File "C:\Users\zhvit\YandexDisk\Python\telegram_bot_smm\system\actions\pars\parsing_group_members.py", line 87, in group_parsing
    entities = all_participants_user(all_participants)
               │                     └ [<telethon.tl.types.User object at 0x0000025715FE8BD0>, <telethon.tl.types.User object at 0x0000025715FE8D10>, <telethon.tl.t...
               └ <function all_participants_user at 0x0000025715EFFB00>

  File "C:\Users\zhvit\YandexDisk\Python\telegram_bot_smm\system\actions\pars\parsing_group_members.py", line 53, in all_participants_user
    getting_user_data(user, entities)
    │                 │     └ []
    │                 └ <telethon.tl.types.User object at 0x0000025715FE8BD0>
    └ <function getting_user_data at 0x0000025715EFFA60>

  File "C:\Users\zhvit\YandexDisk\Python\telegram_bot_smm\system\actions\pars\parsing_group_members.py", line 36, in getting_user_data
    user.status(UserStatusRecently, UserStatusOffline, UserStatusLastWeek, UserStatusLastMonth)):
    │    │      │                   │                  │                   └ <class 'telethon.tl.types.UserStatusLastMonth'>
    │    │      │                   │                  └ <class 'telethon.tl.types.UserStatusLastWeek'>
    │    │      │                   └ <class 'telethon.tl.types.UserStatusOffline'>
    │    │      └ <class 'telethon.tl.types.UserStatusRecently'>
    │    └ <telethon.tl.types.UserStatusOnline object at 0x0000025715FE8B90>
    └ <telethon.tl.types.User object at 0x0000025715FE8BD0>

TypeError: 'UserStatusOnline' object is not callable
2023-11-07 10:38:23.445 | ERROR    | __main__:<module>:20 - 'UserStatusOnline' object is not callable
Traceback (most recent call last):

> File "C:\Users\zhvit\YandexDisk\Python\telegram_bot_smm\main.py", line 18, in <module>
    launching_the_program_with_account_verification()
    └ <function launching_the_program_with_account_verification at 0x0000025715F12520>

  File "C:\Users\zhvit\YandexDisk\Python\telegram_bot_smm\main.py", line 13, in launching_the_program_with_account_verification
    main_menu()  # Основное меню программы
    └ <function main_menu at 0x00000257106BE480>

  File "C:\Users\zhvit\YandexDisk\Python\telegram_bot_smm\system\menu\main_menu_interface.py", line 43, in main_menu
    telegram_parsing_menu()
    └ <function telegram_parsing_menu at 0x0000025715F12660>

  File "C:\Users\zhvit\YandexDisk\Python\telegram_bot_smm\system\menu\main_menu_interface.py", line 143, in telegram_parsing_menu
    main_menu()  # После отработки функции переходим в начальное меню
    └ <function main_menu at 0x00000257106BE480>

  File "C:\Users\zhvit\YandexDisk\Python\telegram_bot_smm\system\menu\main_menu_interface.py", line 43, in main_menu
    telegram_parsing_menu()
    └ <function telegram_parsing_menu at 0x0000025715F12660>

  File "C:\Users\zhvit\YandexDisk\Python\telegram_bot_smm\system\menu\main_menu_interface.py", line 117, in telegram_parsing_menu
    parsing_mass_parsing_of_groups()  # Парсинг участников чата
    └ <function parsing_mass_parsing_of_groups at 0x0000025715EFFBA0>

  File "C:\Users\zhvit\YandexDisk\Python\telegram_bot_smm\system\actions\pars\parsing_group_members.py", line 69, in parsing_mass_parsing_of_groups
    group_parsing(client, groups_wr, phone)  # Parsing групп
    │             │       │          └ '375297929184'
    │             │       └ 'https://t.me/gk_levada'
    │             └ <telethon.client.telegramclient.TelegramClient object at 0x0000025715F567D0>
    └ <function handle_exceptions_pars.<locals>.wrapper at 0x0000025715EFFCE0>

  File "C:\Users\zhvit\YandexDisk\Python\telegram_bot_smm\system\error\telegram_errors.py", line 56, in wrapper
    return func(*args, **kwargs)
           │     │       └ {}
           │     └ (<telethon.client.telegramclient.TelegramClient object at 0x0000025715F567D0>, 'https://t.me/gk_levada', '375297929184')
           └ <function group_parsing at 0x0000025715EFFC40>

  File "C:\Users\zhvit\YandexDisk\Python\telegram_bot_smm\system\actions\pars\parsing_group_members.py", line 87, in group_parsing
    entities = all_participants_user(all_participants)
               │                     └ [<telethon.tl.types.User object at 0x0000025715FE8BD0>, <telethon.tl.types.User object at 0x0000025715FE8D10>, <telethon.tl.t...
               └ <function all_participants_user at 0x0000025715EFFB00>

  File "C:\Users\zhvit\YandexDisk\Python\telegram_bot_smm\system\actions\pars\parsing_group_members.py", line 53, in all_participants_user
    getting_user_data(user, entities)
    │                 │     └ []
    │                 └ <telethon.tl.types.User object at 0x0000025715FE8BD0>
    └ <function getting_user_data at 0x0000025715EFFA60>

  File "C:\Users\zhvit\YandexDisk\Python\telegram_bot_smm\system\actions\pars\parsing_group_members.py", line 36, in getting_user_data
    user.status(UserStatusRecently, UserStatusOffline, UserStatusLastWeek, UserStatusLastMonth)):
    │    │      │                   │                  │                   └ <class 'telethon.tl.types.UserStatusLastMonth'>
    │    │      │                   │                  └ <class 'telethon.tl.types.UserStatusLastWeek'>
    │    │      │                   └ <class 'telethon.tl.types.UserStatusOffline'>
    │    │      └ <class 'telethon.tl.types.UserStatusRecently'>
    │    └ <telethon.tl.types.UserStatusOnline object at 0x0000025715FE8B90>
    └ <telethon.tl.types.User object at 0x0000025715FE8BD0>

TypeError: 'UserStatusOnline' object is not callable
2023-11-07 11:43:15.536 | ERROR    | __main__:<module>:20 - 'charmap' codec can't encode character '\u2661' in position 17: character maps to <undefined>
Traceback (most recent call last):

> File "C:\Users\zhvit\YandexDisk\Python\telegram_bot_smm\main.py", line 18, in <module>
    launching_the_program_with_account_verification()
    └ <function launching_the_program_with_account_verification at 0x000001E69B0D2840>

  File "C:\Users\zhvit\YandexDisk\Python\telegram_bot_smm\main.py", line 12, in launching_the_program_with_account_verification
    deleting_files_by_dictionary()
    └ <function deleting_files_by_dictionary at 0x000001E69B0C7100>

  File "C:\Users\zhvit\YandexDisk\Python\telegram_bot_smm\system\telegram_actions\account_verification.py", line 25, in deleting_files_by_dictionary
    error_sessions = account_verification()
                     └ <function account_verification at 0x000001E69B0C7240>

  File "C:\Users\zhvit\YandexDisk\Python\telegram_bot_smm\system\telegram_actions\account_verification.py", line 63, in account_verification
    print(f"[bold red][!] Account connect {first_name} {last_name} {phone}")
    └ <function print at 0x000001E697ED8EA0>

  File "C:\Users\zhvit\AppData\Local\Programs\Python\Python311\Lib\site-packages\rich\__init__.py", line 74, in print
    return write_console.print(*objects, sep=sep, end=end)
           │             │      │            │        └ '\n'
           │             │      │            └ ' '
           │             │      └ ('[bold red][!] Account connect ♡  380968873601',)
           │             └ <function Console.print at 0x000001E69B03C680>
           └ <console width=79 None>
  File "C:\Users\zhvit\AppData\Local\Programs\Python\Python311\Lib\site-packages\rich\console.py", line 1672, in print
    with self:
         └ <console width=79 None>
  File "C:\Users\zhvit\AppData\Local\Programs\Python\Python311\Lib\site-packages\rich\console.py", line 864, in __exit__
    self._exit_buffer()
    │    └ <function Console._exit_buffer at 0x000001E69B036B60>
    └ <console width=79 None>
  File "C:\Users\zhvit\AppData\Local\Programs\Python\Python311\Lib\site-packages\rich\console.py", line 822, in _exit_buffer
    self._check_buffer()
    │    └ <function Console._check_buffer at 0x000001E69B03CAE0>
    └ <console width=79 None>
  File "C:\Users\zhvit\AppData\Local\Programs\Python\Python311\Lib\site-packages\rich\console.py", line 2026, in _check_buffer
    legacy_windows_render(buffer, LegacyWindowsTerm(self.file))
    │                     │       │                 │    └ <property object at 0x000001E69B026E30>
    │                     │       │                 └ <console width=79 None>
    │                     │       └ <class 'rich._win32_console.LegacyWindowsTerm'>
    │                     └ [Segment('[', Style(color=Color('red', ColorType.STANDARD, number=1), bold=True)), Segment('!', Style(color=Color('red', Colo...
    └ <function legacy_windows_render at 0x000001E69B0D3100>
  File "C:\Users\zhvit\AppData\Local\Programs\Python\Python311\Lib\site-packages\rich\_windows_renderer.py", line 17, in legacy_windows_render
    term.write_styled(text, style)
    │    │            │     └ Style(color=Color('red', ColorType.STANDARD, number=1), bold=True)
    │    │            └ ' Account connect ♡  '
    │    └ <function LegacyWindowsTerm.write_styled at 0x000001E69B03E3E0>
    └ <rich._win32_console.LegacyWindowsTerm object at 0x000001E69B10FD90>
  File "C:\Users\zhvit\AppData\Local\Programs\Python\Python311\Lib\site-packages\rich\_win32_console.py", line 442, in write_styled
    self.write_text(text)
    │    │          └ ' Account connect ♡  '
    │    └ <function LegacyWindowsTerm.write_text at 0x000001E69B03E340>
    └ <rich._win32_console.LegacyWindowsTerm object at 0x000001E69B10FD90>
  File "C:\Users\zhvit\AppData\Local\Programs\Python\Python311\Lib\site-packages\rich\_win32_console.py", line 403, in write_text
    self.write(text)
    │    │     └ ' Account connect ♡  '
    │    └ <built-in method write of _io.TextIOWrapper object at 0x000001E6955BFE00>
    └ <rich._win32_console.LegacyWindowsTerm object at 0x000001E69B10FD90>
  File "C:\Users\zhvit\AppData\Local\Programs\Python\Python311\Lib\encodings\cp1251.py", line 19, in encode
    return codecs.charmap_encode(input,self.errors,encoding_table)[0]
           │      │              │     │    │      └ <EncodingMap object at 0x000001E695485A80>
           │      │              │     │    └ 'strict'
           │      │              │     └ <encodings.cp1251.IncrementalEncoder object at 0x000001E6956992D0>
           │      │              └ ' Account connect ♡  '
           │      └ <built-in function charmap_encode>
           └ <module 'codecs' (frozen)>

UnicodeEncodeError: 'charmap' codec can't encode character '\u2661' in position 17: character maps to <undefined>
2023-11-07 11:43:15.536 | ERROR    | __main__:<module>:20 - 'charmap' codec can't encode character '\u2661' in position 17: character maps to <undefined>
Traceback (most recent call last):

> File "C:\Users\zhvit\YandexDisk\Python\telegram_bot_smm\main.py", line 18, in <module>
    launching_the_program_with_account_verification()
    └ <function launching_the_program_with_account_verification at 0x000001E69B0D2840>

  File "C:\Users\zhvit\YandexDisk\Python\telegram_bot_smm\main.py", line 12, in launching_the_program_with_account_verification
    deleting_files_by_dictionary()
    └ <function deleting_files_by_dictionary at 0x000001E69B0C7100>

  File "C:\Users\zhvit\YandexDisk\Python\telegram_bot_smm\system\telegram_actions\account_verification.py", line 25, in deleting_files_by_dictionary
    error_sessions = account_verification()
                     └ <function account_verification at 0x000001E69B0C7240>

  File "C:\Users\zhvit\YandexDisk\Python\telegram_bot_smm\system\telegram_actions\account_verification.py", line 63, in account_verification
    print(f"[bold red][!] Account connect {first_name} {last_name} {phone}")
    └ <function print at 0x000001E697ED8EA0>

  File "C:\Users\zhvit\AppData\Local\Programs\Python\Python311\Lib\site-packages\rich\__init__.py", line 74, in print
    return write_console.print(*objects, sep=sep, end=end)
           │             │      │            │        └ '\n'
           │             │      │            └ ' '
           │             │      └ ('[bold red][!] Account connect ♡  380968873601',)
           │             └ <function Console.print at 0x000001E69B03C680>
           └ <console width=79 None>
  File "C:\Users\zhvit\AppData\Local\Programs\Python\Python311\Lib\site-packages\rich\console.py", line 1672, in print
    with self:
         └ <console width=79 None>
  File "C:\Users\zhvit\AppData\Local\Programs\Python\Python311\Lib\site-packages\rich\console.py", line 864, in __exit__
    self._exit_buffer()
    │    └ <function Console._exit_buffer at 0x000001E69B036B60>
    └ <console width=79 None>
  File "C:\Users\zhvit\AppData\Local\Programs\Python\Python311\Lib\site-packages\rich\console.py", line 822, in _exit_buffer
    self._check_buffer()
    │    └ <function Console._check_buffer at 0x000001E69B03CAE0>
    └ <console width=79 None>
  File "C:\Users\zhvit\AppData\Local\Programs\Python\Python311\Lib\site-packages\rich\console.py", line 2026, in _check_buffer
    legacy_windows_render(buffer, LegacyWindowsTerm(self.file))
    │                     │       │                 │    └ <property object at 0x000001E69B026E30>
    │                     │       │                 └ <console width=79 None>
    │                     │       └ <class 'rich._win32_console.LegacyWindowsTerm'>
    │                     └ [Segment('[', Style(color=Color('red', ColorType.STANDARD, number=1), bold=True)), Segment('!', Style(color=Color('red', Colo...
    └ <function legacy_windows_render at 0x000001E69B0D3100>
  File "C:\Users\zhvit\AppData\Local\Programs\Python\Python311\Lib\site-packages\rich\_windows_renderer.py", line 17, in legacy_windows_render
    term.write_styled(text, style)
    │    │            │     └ Style(color=Color('red', ColorType.STANDARD, number=1), bold=True)
    │    │            └ ' Account connect ♡  '
    │    └ <function LegacyWindowsTerm.write_styled at 0x000001E69B03E3E0>
    └ <rich._win32_console.LegacyWindowsTerm object at 0x000001E69B10FD90>
  File "C:\Users\zhvit\AppData\Local\Programs\Python\Python311\Lib\site-packages\rich\_win32_console.py", line 442, in write_styled
    self.write_text(text)
    │    │          └ ' Account connect ♡  '
    │    └ <function LegacyWindowsTerm.write_text at 0x000001E69B03E340>
    └ <rich._win32_console.LegacyWindowsTerm object at 0x000001E69B10FD90>
  File "C:\Users\zhvit\AppData\Local\Programs\Python\Python311\Lib\site-packages\rich\_win32_console.py", line 403, in write_text
    self.write(text)
    │    │     └ ' Account connect ♡  '
    │    └ <built-in method write of _io.TextIOWrapper object at 0x000001E6955BFE00>
    └ <rich._win32_console.LegacyWindowsTerm object at 0x000001E69B10FD90>
  File "C:\Users\zhvit\AppData\Local\Programs\Python\Python311\Lib\encodings\cp1251.py", line 19, in encode
    return codecs.charmap_encode(input,self.errors,encoding_table)[0]
           │      │              │     │    │      └ <EncodingMap object at 0x000001E695485A80>
           │      │              │     │    └ 'strict'
           │      │              │     └ <encodings.cp1251.IncrementalEncoder object at 0x000001E6956992D0>
           │      │              └ ' Account connect ♡  '
           │      └ <built-in function charmap_encode>
           └ <module 'codecs' (frozen)>

UnicodeEncodeError: 'charmap' codec can't encode character '\u2661' in position 17: character maps to <undefined>
2023-11-07 11:56:55.754 | ERROR    | __main__:<module>:20 - 'UserStatusOffline' object is not callable
Traceback (most recent call last):

> File "C:\Users\zhvit\YandexDisk\Python\telegram_bot_smm\main.py", line 18, in <module>
    launching_the_program_with_account_verification()
    └ <function launching_the_program_with_account_verification at 0x0000015070122520>

  File "C:\Users\zhvit\YandexDisk\Python\telegram_bot_smm\main.py", line 13, in launching_the_program_with_account_verification
    main_menu()  # Основное меню программы
    └ <function main_menu at 0x000001506A89E480>

  File "C:\Users\zhvit\YandexDisk\Python\telegram_bot_smm\system\menu\main_menu_interface.py", line 43, in main_menu
    telegram_parsing_menu()
    └ <function telegram_parsing_menu at 0x0000015070122660>

  File "C:\Users\zhvit\YandexDisk\Python\telegram_bot_smm\system\menu\main_menu_interface.py", line 117, in telegram_parsing_menu
    parsing_mass_parsing_of_groups()  # Парсинг участников чата
    └ <function parsing_mass_parsing_of_groups at 0x0000015070113BA0>

  File "C:\Users\zhvit\YandexDisk\Python\telegram_bot_smm\system\actions\pars\parsing_group_members.py", line 69, in parsing_mass_parsing_of_groups
    group_parsing(client, groups_wr, phone)  # Parsing групп
    │             │       │          └ '375297929184'
    │             │       └ 'https://t.me/gk_levada'
    │             └ <telethon.client.telegramclient.TelegramClient object at 0x000001506EAF2C50>
    └ <function handle_exceptions_pars.<locals>.wrapper at 0x0000015070113CE0>

  File "C:\Users\zhvit\YandexDisk\Python\telegram_bot_smm\system\error\telegram_errors.py", line 56, in wrapper
    return func(*args, **kwargs)
           │     │       └ {}
           │     └ (<telethon.client.telegramclient.TelegramClient object at 0x000001506EAF2C50>, 'https://t.me/gk_levada', '375297929184')
           └ <function group_parsing at 0x0000015070113C40>

  File "C:\Users\zhvit\YandexDisk\Python\telegram_bot_smm\system\actions\pars\parsing_group_members.py", line 87, in group_parsing
    entities = all_participants_user(all_participants)
               │                     └ [<telethon.tl.types.User object at 0x00000150701EEBD0>, <telethon.tl.types.User object at 0x00000150701EED50>, <telethon.tl.t...
               └ <function all_participants_user at 0x0000015070113B00>

  File "C:\Users\zhvit\YandexDisk\Python\telegram_bot_smm\system\actions\pars\parsing_group_members.py", line 53, in all_participants_user
    getting_user_data(user, entities)
    │                 │     └ []
    │                 └ <telethon.tl.types.User object at 0x00000150701EEBD0>
    └ <function getting_user_data at 0x0000015070113A60>

  File "C:\Users\zhvit\YandexDisk\Python\telegram_bot_smm\system\actions\pars\parsing_group_members.py", line 35, in getting_user_data
    if isinstance(user.status(UserStatusRecently, UserStatusOffline, UserStatusLastWeek, UserStatusLastMonth)):
                  │    │      │                   │                  │                   └ <class 'telethon.tl.types.UserStatusLastMonth'>
                  │    │      │                   │                  └ <class 'telethon.tl.types.UserStatusLastWeek'>
                  │    │      │                   └ <class 'telethon.tl.types.UserStatusOffline'>
                  │    │      └ <class 'telethon.tl.types.UserStatusRecently'>
                  │    └ <telethon.tl.types.UserStatusOffline object at 0x00000150701EEB90>
                  └ <telethon.tl.types.User object at 0x00000150701EEBD0>

TypeError: 'UserStatusOffline' object is not callable
2023-11-07 11:56:55.754 | ERROR    | __main__:<module>:20 - 'UserStatusOffline' object is not callable
Traceback (most recent call last):

> File "C:\Users\zhvit\YandexDisk\Python\telegram_bot_smm\main.py", line 18, in <module>
    launching_the_program_with_account_verification()
    └ <function launching_the_program_with_account_verification at 0x0000015070122520>

  File "C:\Users\zhvit\YandexDisk\Python\telegram_bot_smm\main.py", line 13, in launching_the_program_with_account_verification
    main_menu()  # Основное меню программы
    └ <function main_menu at 0x000001506A89E480>

  File "C:\Users\zhvit\YandexDisk\Python\telegram_bot_smm\system\menu\main_menu_interface.py", line 43, in main_menu
    telegram_parsing_menu()
    └ <function telegram_parsing_menu at 0x0000015070122660>

  File "C:\Users\zhvit\YandexDisk\Python\telegram_bot_smm\system\menu\main_menu_interface.py", line 117, in telegram_parsing_menu
    parsing_mass_parsing_of_groups()  # Парсинг участников чата
    └ <function parsing_mass_parsing_of_groups at 0x0000015070113BA0>

  File "C:\Users\zhvit\YandexDisk\Python\telegram_bot_smm\system\actions\pars\parsing_group_members.py", line 69, in parsing_mass_parsing_of_groups
    group_parsing(client, groups_wr, phone)  # Parsing групп
    │             │       │          └ '375297929184'
    │             │       └ 'https://t.me/gk_levada'
    │             └ <telethon.client.telegramclient.TelegramClient object at 0x000001506EAF2C50>
    └ <function handle_exceptions_pars.<locals>.wrapper at 0x0000015070113CE0>

  File "C:\Users\zhvit\YandexDisk\Python\telegram_bot_smm\system\error\telegram_errors.py", line 56, in wrapper
    return func(*args, **kwargs)
           │     │       └ {}
           │     └ (<telethon.client.telegramclient.TelegramClient object at 0x000001506EAF2C50>, 'https://t.me/gk_levada', '375297929184')
           └ <function group_parsing at 0x0000015070113C40>

  File "C:\Users\zhvit\YandexDisk\Python\telegram_bot_smm\system\actions\pars\parsing_group_members.py", line 87, in group_parsing
    entities = all_participants_user(all_participants)
               │                     └ [<telethon.tl.types.User object at 0x00000150701EEBD0>, <telethon.tl.types.User object at 0x00000150701EED50>, <telethon.tl.t...
               └ <function all_participants_user at 0x0000015070113B00>

  File "C:\Users\zhvit\YandexDisk\Python\telegram_bot_smm\system\actions\pars\parsing_group_members.py", line 53, in all_participants_user
    getting_user_data(user, entities)
    │                 │     └ []
    │                 └ <telethon.tl.types.User object at 0x00000150701EEBD0>
    └ <function getting_user_data at 0x0000015070113A60>

  File "C:\Users\zhvit\YandexDisk\Python\telegram_bot_smm\system\actions\pars\parsing_group_members.py", line 35, in getting_user_data
    if isinstance(user.status(UserStatusRecently, UserStatusOffline, UserStatusLastWeek, UserStatusLastMonth)):
                  │    │      │                   │                  │                   └ <class 'telethon.tl.types.UserStatusLastMonth'>
                  │    │      │                   │                  └ <class 'telethon.tl.types.UserStatusLastWeek'>
                  │    │      │                   └ <class 'telethon.tl.types.UserStatusOffline'>
                  │    │      └ <class 'telethon.tl.types.UserStatusRecently'>
                  │    └ <telethon.tl.types.UserStatusOffline object at 0x00000150701EEB90>
                  └ <telethon.tl.types.User object at 0x00000150701EEBD0>

TypeError: 'UserStatusOffline' object is not callable
2023-11-07 12:05:32.312 | ERROR    | __main__:<module>:20 - 'UserStatusOffline' object is not callable
Traceback (most recent call last):

> File "C:\Users\zhvit\YandexDisk\Python\telegram_bot_smm\main.py", line 18, in <module>
    launching_the_program_with_account_verification()
    └ <function launching_the_program_with_account_verification at 0x0000019AA1B4E480>

  File "C:\Users\zhvit\YandexDisk\Python\telegram_bot_smm\main.py", line 13, in launching_the_program_with_account_verification
    main_menu()  # Основное меню программы
    └ <function main_menu at 0x0000019A9D28E480>

  File "C:\Users\zhvit\YandexDisk\Python\telegram_bot_smm\system\menu\main_menu_interface.py", line 43, in main_menu
    telegram_parsing_menu()
    └ <function telegram_parsing_menu at 0x0000019AA1B4E5C0>

  File "C:\Users\zhvit\YandexDisk\Python\telegram_bot_smm\system\menu\main_menu_interface.py", line 117, in telegram_parsing_menu
    parsing_mass_parsing_of_groups()  # Парсинг участников чата
    └ <function parsing_mass_parsing_of_groups at 0x0000019AA1B3FBA0>

  File "C:\Users\zhvit\YandexDisk\Python\telegram_bot_smm\system\actions\pars\parsing_group_members.py", line 69, in parsing_mass_parsing_of_groups
    group_parsing(client, groups_wr, phone)  # Parsing групп
    │             │       │          └ '375297929184'
    │             │       └ 'https://t.me/gk_levada'
    │             └ <telethon.client.telegramclient.TelegramClient object at 0x0000019AA2B46E90>
    └ <function handle_exceptions_pars.<locals>.wrapper at 0x0000019AA1B3FCE0>

  File "C:\Users\zhvit\YandexDisk\Python\telegram_bot_smm\system\error\telegram_errors.py", line 56, in wrapper
    return func(*args, **kwargs)
           │     │       └ {}
           │     └ (<telethon.client.telegramclient.TelegramClient object at 0x0000019AA2B46E90>, 'https://t.me/gk_levada', '375297929184')
           └ <function group_parsing at 0x0000019AA1B3FC40>

  File "C:\Users\zhvit\YandexDisk\Python\telegram_bot_smm\system\actions\pars\parsing_group_members.py", line 87, in group_parsing
    entities = all_participants_user(all_participants)
               │                     └ [<telethon.tl.types.User object at 0x0000019AA2BF5ED0>, <telethon.tl.types.User object at 0x0000019AA2BF6050>, <telethon.tl.t...
               └ <function all_participants_user at 0x0000019AA1B3FA60>

  File "C:\Users\zhvit\YandexDisk\Python\telegram_bot_smm\system\actions\pars\parsing_group_members.py", line 53, in all_participants_user
    getting_user_data(user, entities)
    │                 │     └ []
    │                 └ <telethon.tl.types.User object at 0x0000019AA2BF5ED0>
    └ <function getting_user_data at 0x0000019AA1B3F880>

  File "C:\Users\zhvit\YandexDisk\Python\telegram_bot_smm\system\actions\pars\parsing_group_members.py", line 35, in getting_user_data
    if isinstance(user.status(UserStatusRecently, UserStatusOnline, UserStatusLastWeek, UserStatusLastMonth)):
                  │    │      │                   │                 │                   └ <class 'telethon.tl.types.UserStatusLastMonth'>
                  │    │      │                   │                 └ <class 'telethon.tl.types.UserStatusLastWeek'>
                  │    │      │                   └ <class 'telethon.tl.types.UserStatusOnline'>
                  │    │      └ <class 'telethon.tl.types.UserStatusRecently'>
                  │    └ <telethon.tl.types.UserStatusOffline object at 0x0000019AA2BF5E90>
                  └ <telethon.tl.types.User object at 0x0000019AA2BF5ED0>

TypeError: 'UserStatusOffline' object is not callable
2023-11-07 12:05:32.312 | ERROR    | __main__:<module>:20 - 'UserStatusOffline' object is not callable
Traceback (most recent call last):

> File "C:\Users\zhvit\YandexDisk\Python\telegram_bot_smm\main.py", line 18, in <module>
    launching_the_program_with_account_verification()
    └ <function launching_the_program_with_account_verification at 0x0000019AA1B4E480>

  File "C:\Users\zhvit\YandexDisk\Python\telegram_bot_smm\main.py", line 13, in launching_the_program_with_account_verification
    main_menu()  # Основное меню программы
    └ <function main_menu at 0x0000019A9D28E480>

  File "C:\Users\zhvit\YandexDisk\Python\telegram_bot_smm\system\menu\main_menu_interface.py", line 43, in main_menu
    telegram_parsing_menu()
    └ <function telegram_parsing_menu at 0x0000019AA1B4E5C0>

  File "C:\Users\zhvit\YandexDisk\Python\telegram_bot_smm\system\menu\main_menu_interface.py", line 117, in telegram_parsing_menu
    parsing_mass_parsing_of_groups()  # Парсинг участников чата
    └ <function parsing_mass_parsing_of_groups at 0x0000019AA1B3FBA0>

  File "C:\Users\zhvit\YandexDisk\Python\telegram_bot_smm\system\actions\pars\parsing_group_members.py", line 69, in parsing_mass_parsing_of_groups
    group_parsing(client, groups_wr, phone)  # Parsing групп
    │             │       │          └ '375297929184'
    │             │       └ 'https://t.me/gk_levada'
    │             └ <telethon.client.telegramclient.TelegramClient object at 0x0000019AA2B46E90>
    └ <function handle_exceptions_pars.<locals>.wrapper at 0x0000019AA1B3FCE0>

  File "C:\Users\zhvit\YandexDisk\Python\telegram_bot_smm\system\error\telegram_errors.py", line 56, in wrapper
    return func(*args, **kwargs)
           │     │       └ {}
           │     └ (<telethon.client.telegramclient.TelegramClient object at 0x0000019AA2B46E90>, 'https://t.me/gk_levada', '375297929184')
           └ <function group_parsing at 0x0000019AA1B3FC40>

  File "C:\Users\zhvit\YandexDisk\Python\telegram_bot_smm\system\actions\pars\parsing_group_members.py", line 87, in group_parsing
    entities = all_participants_user(all_participants)
               │                     └ [<telethon.tl.types.User object at 0x0000019AA2BF5ED0>, <telethon.tl.types.User object at 0x0000019AA2BF6050>, <telethon.tl.t...
               └ <function all_participants_user at 0x0000019AA1B3FA60>

  File "C:\Users\zhvit\YandexDisk\Python\telegram_bot_smm\system\actions\pars\parsing_group_members.py", line 53, in all_participants_user
    getting_user_data(user, entities)
    │                 │     └ []
    │                 └ <telethon.tl.types.User object at 0x0000019AA2BF5ED0>
    └ <function getting_user_data at 0x0000019AA1B3F880>

  File "C:\Users\zhvit\YandexDisk\Python\telegram_bot_smm\system\actions\pars\parsing_group_members.py", line 35, in getting_user_data
    if isinstance(user.status(UserStatusRecently, UserStatusOnline, UserStatusLastWeek, UserStatusLastMonth)):
                  │    │      │                   │                 │                   └ <class 'telethon.tl.types.UserStatusLastMonth'>
                  │    │      │                   │                 └ <class 'telethon.tl.types.UserStatusLastWeek'>
                  │    │      │                   └ <class 'telethon.tl.types.UserStatusOnline'>
                  │    │      └ <class 'telethon.tl.types.UserStatusRecently'>
                  │    └ <telethon.tl.types.UserStatusOffline object at 0x0000019AA2BF5E90>
                  └ <telethon.tl.types.User object at 0x0000019AA2BF5ED0>

TypeError: 'UserStatusOffline' object is not callable
2023-11-07 12:08:46.172 | ERROR    | __main__:<module>:20 - 'UserStatusOnline' object is not callable
Traceback (most recent call last):

> File "C:\Users\zhvit\YandexDisk\Python\telegram_bot_smm\main.py", line 18, in <module>
    launching_the_program_with_account_verification()
    └ <function launching_the_program_with_account_verification at 0x000001E3138F2520>

  File "C:\Users\zhvit\YandexDisk\Python\telegram_bot_smm\main.py", line 13, in launching_the_program_with_account_verification
    main_menu()  # Основное меню программы
    └ <function main_menu at 0x000001E30F0EE480>

  File "C:\Users\zhvit\YandexDisk\Python\telegram_bot_smm\system\menu\main_menu_interface.py", line 43, in main_menu
    telegram_parsing_menu()
    └ <function telegram_parsing_menu at 0x000001E3138F2660>

  File "C:\Users\zhvit\YandexDisk\Python\telegram_bot_smm\system\menu\main_menu_interface.py", line 117, in telegram_parsing_menu
    parsing_mass_parsing_of_groups()  # Парсинг участников чата
    └ <function parsing_mass_parsing_of_groups at 0x000001E3138DFBA0>

  File "C:\Users\zhvit\YandexDisk\Python\telegram_bot_smm\system\actions\pars\parsing_group_members.py", line 69, in parsing_mass_parsing_of_groups
    group_parsing(client, groups_wr, phone)  # Parsing групп
    │             │       │          └ '79017164904'
    │             │       └ 'https://t.me/gk_levada'
    │             └ <telethon.client.telegramclient.TelegramClient object at 0x000001E3148D6110>
    └ <function handle_exceptions_pars.<locals>.wrapper at 0x000001E3138DFCE0>

  File "C:\Users\zhvit\YandexDisk\Python\telegram_bot_smm\system\error\telegram_errors.py", line 56, in wrapper
    return func(*args, **kwargs)
           │     │       └ {}
           │     └ (<telethon.client.telegramclient.TelegramClient object at 0x000001E3148D6110>, 'https://t.me/gk_levada', '79017164904')
           └ <function group_parsing at 0x000001E3138DFC40>

  File "C:\Users\zhvit\YandexDisk\Python\telegram_bot_smm\system\actions\pars\parsing_group_members.py", line 87, in group_parsing
    entities = all_participants_user(all_participants)
               │                     └ [<telethon.tl.types.User object at 0x000001E314926890>, <telethon.tl.types.User object at 0x000001E3149269D0>, <telethon.tl.t...
               └ <function all_participants_user at 0x000001E3138DFB00>

  File "C:\Users\zhvit\YandexDisk\Python\telegram_bot_smm\system\actions\pars\parsing_group_members.py", line 53, in all_participants_user
    getting_user_data(user, entities)
    │                 │     └ []
    │                 └ <telethon.tl.types.User object at 0x000001E314926890>
    └ <function getting_user_data at 0x000001E3138DFA60>

  File "C:\Users\zhvit\YandexDisk\Python\telegram_bot_smm\system\actions\pars\parsing_group_members.py", line 35, in getting_user_data
    if isinstance(user.status(UserStatusRecently, UserStatusOnline, UserStatusLastWeek, UserStatusLastMonth)):
                  │    │      │                   │                 │                   └ <class 'telethon.tl.types.UserStatusLastMonth'>
                  │    │      │                   │                 └ <class 'telethon.tl.types.UserStatusLastWeek'>
                  │    │      │                   └ <class 'telethon.tl.types.UserStatusOnline'>
                  │    │      └ <class 'telethon.tl.types.UserStatusRecently'>
                  │    └ <telethon.tl.types.UserStatusOnline object at 0x000001E314926850>
                  └ <telethon.tl.types.User object at 0x000001E314926890>

TypeError: 'UserStatusOnline' object is not callable
2023-11-07 12:08:46.172 | ERROR    | __main__:<module>:20 - 'UserStatusOnline' object is not callable
Traceback (most recent call last):

> File "C:\Users\zhvit\YandexDisk\Python\telegram_bot_smm\main.py", line 18, in <module>
    launching_the_program_with_account_verification()
    └ <function launching_the_program_with_account_verification at 0x000001E3138F2520>

  File "C:\Users\zhvit\YandexDisk\Python\telegram_bot_smm\main.py", line 13, in launching_the_program_with_account_verification
    main_menu()  # Основное меню программы
    └ <function main_menu at 0x000001E30F0EE480>

  File "C:\Users\zhvit\YandexDisk\Python\telegram_bot_smm\system\menu\main_menu_interface.py", line 43, in main_menu
    telegram_parsing_menu()
    └ <function telegram_parsing_menu at 0x000001E3138F2660>

  File "C:\Users\zhvit\YandexDisk\Python\telegram_bot_smm\system\menu\main_menu_interface.py", line 117, in telegram_parsing_menu
    parsing_mass_parsing_of_groups()  # Парсинг участников чата
    └ <function parsing_mass_parsing_of_groups at 0x000001E3138DFBA0>

  File "C:\Users\zhvit\YandexDisk\Python\telegram_bot_smm\system\actions\pars\parsing_group_members.py", line 69, in parsing_mass_parsing_of_groups
    group_parsing(client, groups_wr, phone)  # Parsing групп
    │             │       │          └ '79017164904'
    │             │       └ 'https://t.me/gk_levada'
    │             └ <telethon.client.telegramclient.TelegramClient object at 0x000001E3148D6110>
    └ <function handle_exceptions_pars.<locals>.wrapper at 0x000001E3138DFCE0>

  File "C:\Users\zhvit\YandexDisk\Python\telegram_bot_smm\system\error\telegram_errors.py", line 56, in wrapper
    return func(*args, **kwargs)
           │     │       └ {}
           │     └ (<telethon.client.telegramclient.TelegramClient object at 0x000001E3148D6110>, 'https://t.me/gk_levada', '79017164904')
           └ <function group_parsing at 0x000001E3138DFC40>

  File "C:\Users\zhvit\YandexDisk\Python\telegram_bot_smm\system\actions\pars\parsing_group_members.py", line 87, in group_parsing
    entities = all_participants_user(all_participants)
               │                     └ [<telethon.tl.types.User object at 0x000001E314926890>, <telethon.tl.types.User object at 0x000001E3149269D0>, <telethon.tl.t...
               └ <function all_participants_user at 0x000001E3138DFB00>

  File "C:\Users\zhvit\YandexDisk\Python\telegram_bot_smm\system\actions\pars\parsing_group_members.py", line 53, in all_participants_user
    getting_user_data(user, entities)
    │                 │     └ []
    │                 └ <telethon.tl.types.User object at 0x000001E314926890>
    └ <function getting_user_data at 0x000001E3138DFA60>

  File "C:\Users\zhvit\YandexDisk\Python\telegram_bot_smm\system\actions\pars\parsing_group_members.py", line 35, in getting_user_data
    if isinstance(user.status(UserStatusRecently, UserStatusOnline, UserStatusLastWeek, UserStatusLastMonth)):
                  │    │      │                   │                 │                   └ <class 'telethon.tl.types.UserStatusLastMonth'>
                  │    │      │                   │                 └ <class 'telethon.tl.types.UserStatusLastWeek'>
                  │    │      │                   └ <class 'telethon.tl.types.UserStatusOnline'>
                  │    │      └ <class 'telethon.tl.types.UserStatusRecently'>
                  │    └ <telethon.tl.types.UserStatusOnline object at 0x000001E314926850>
                  └ <telethon.tl.types.User object at 0x000001E314926890>

TypeError: 'UserStatusOnline' object is not callable
2023-11-07 12:09:41.371 | ERROR    | __main__:<module>:20 - 'UserStatusOnline' object is not callable
Traceback (most recent call last):

> File "C:\Users\zhvit\YandexDisk\Python\telegram_bot_smm\main.py", line 18, in <module>
    launching_the_program_with_account_verification()
    └ <function launching_the_program_with_account_verification at 0x000001FAA360E480>

  File "C:\Users\zhvit\YandexDisk\Python\telegram_bot_smm\main.py", line 13, in launching_the_program_with_account_verification
    main_menu()  # Основное меню программы
    └ <function main_menu at 0x000001FA9DDCE480>

  File "C:\Users\zhvit\YandexDisk\Python\telegram_bot_smm\system\menu\main_menu_interface.py", line 43, in main_menu
    telegram_parsing_menu()
    └ <function telegram_parsing_menu at 0x000001FAA360E5C0>

  File "C:\Users\zhvit\YandexDisk\Python\telegram_bot_smm\system\menu\main_menu_interface.py", line 117, in telegram_parsing_menu
    parsing_mass_parsing_of_groups()  # Парсинг участников чата
    └ <function parsing_mass_parsing_of_groups at 0x000001FAA35FFBA0>

  File "C:\Users\zhvit\YandexDisk\Python\telegram_bot_smm\system\actions\pars\parsing_group_members.py", line 69, in parsing_mass_parsing_of_groups
    group_parsing(client, groups_wr, phone)  # Parsing групп
    │             │       │          └ '79017164904'
    │             │       └ 'https://t.me/gk_levada'
    │             └ <telethon.client.telegramclient.TelegramClient object at 0x000001FAA3588490>
    └ <function handle_exceptions_pars.<locals>.wrapper at 0x000001FAA35FFCE0>

  File "C:\Users\zhvit\YandexDisk\Python\telegram_bot_smm\system\error\telegram_errors.py", line 56, in wrapper
    return func(*args, **kwargs)
           │     │       └ {}
           │     └ (<telethon.client.telegramclient.TelegramClient object at 0x000001FAA3588490>, 'https://t.me/gk_levada', '79017164904')
           └ <function group_parsing at 0x000001FAA35FFC40>

  File "C:\Users\zhvit\YandexDisk\Python\telegram_bot_smm\system\actions\pars\parsing_group_members.py", line 87, in group_parsing
    entities = all_participants_user(all_participants)
               │                     └ [<telethon.tl.types.User object at 0x000001FAA367F290>, <telethon.tl.types.User object at 0x000001FAA367F390>, <telethon.tl.t...
               └ <function all_participants_user at 0x000001FAA35FFA60>

  File "C:\Users\zhvit\YandexDisk\Python\telegram_bot_smm\system\actions\pars\parsing_group_members.py", line 53, in all_participants_user
    getting_user_data(user, entities)
    │                 │     └ []
    │                 └ <telethon.tl.types.User object at 0x000001FAA367F290>
    └ <function getting_user_data at 0x000001FAA35FF880>

  File "C:\Users\zhvit\YandexDisk\Python\telegram_bot_smm\system\actions\pars\parsing_group_members.py", line 35, in getting_user_data
    if isinstance(user.status(UserStatusRecently, UserStatusOnline, UserStatusLastWeek, UserStatusLastMonth)):
                  │    │      │                   │                 │                   └ <class 'telethon.tl.types.UserStatusLastMonth'>
                  │    │      │                   │                 └ <class 'telethon.tl.types.UserStatusLastWeek'>
                  │    │      │                   └ <class 'telethon.tl.types.UserStatusOnline'>
                  │    │      └ <class 'telethon.tl.types.UserStatusRecently'>
                  │    └ <telethon.tl.types.UserStatusOnline object at 0x000001FAA367F250>
                  └ <telethon.tl.types.User object at 0x000001FAA367F290>

TypeError: 'UserStatusOnline' object is not callable
2023-11-07 12:09:41.371 | ERROR    | __main__:<module>:20 - 'UserStatusOnline' object is not callable
Traceback (most recent call last):

> File "C:\Users\zhvit\YandexDisk\Python\telegram_bot_smm\main.py", line 18, in <module>
    launching_the_program_with_account_verification()
    └ <function launching_the_program_with_account_verification at 0x000001FAA360E480>

  File "C:\Users\zhvit\YandexDisk\Python\telegram_bot_smm\main.py", line 13, in launching_the_program_with_account_verification
    main_menu()  # Основное меню программы
    └ <function main_menu at 0x000001FA9DDCE480>

  File "C:\Users\zhvit\YandexDisk\Python\telegram_bot_smm\system\menu\main_menu_interface.py", line 43, in main_menu
    telegram_parsing_menu()
    └ <function telegram_parsing_menu at 0x000001FAA360E5C0>

  File "C:\Users\zhvit\YandexDisk\Python\telegram_bot_smm\system\menu\main_menu_interface.py", line 117, in telegram_parsing_menu
    parsing_mass_parsing_of_groups()  # Парсинг участников чата
    └ <function parsing_mass_parsing_of_groups at 0x000001FAA35FFBA0>

  File "C:\Users\zhvit\YandexDisk\Python\telegram_bot_smm\system\actions\pars\parsing_group_members.py", line 69, in parsing_mass_parsing_of_groups
    group_parsing(client, groups_wr, phone)  # Parsing групп
    │             │       │          └ '79017164904'
    │             │       └ 'https://t.me/gk_levada'
    │             └ <telethon.client.telegramclient.TelegramClient object at 0x000001FAA3588490>
    └ <function handle_exceptions_pars.<locals>.wrapper at 0x000001FAA35FFCE0>

  File "C:\Users\zhvit\YandexDisk\Python\telegram_bot_smm\system\error\telegram_errors.py", line 56, in wrapper
    return func(*args, **kwargs)
           │     │       └ {}
           │     └ (<telethon.client.telegramclient.TelegramClient object at 0x000001FAA3588490>, 'https://t.me/gk_levada', '79017164904')
           └ <function group_parsing at 0x000001FAA35FFC40>

  File "C:\Users\zhvit\YandexDisk\Python\telegram_bot_smm\system\actions\pars\parsing_group_members.py", line 87, in group_parsing
    entities = all_participants_user(all_participants)
               │                     └ [<telethon.tl.types.User object at 0x000001FAA367F290>, <telethon.tl.types.User object at 0x000001FAA367F390>, <telethon.tl.t...
               └ <function all_participants_user at 0x000001FAA35FFA60>

  File "C:\Users\zhvit\YandexDisk\Python\telegram_bot_smm\system\actions\pars\parsing_group_members.py", line 53, in all_participants_user
    getting_user_data(user, entities)
    │                 │     └ []
    │                 └ <telethon.tl.types.User object at 0x000001FAA367F290>
    └ <function getting_user_data at 0x000001FAA35FF880>

  File "C:\Users\zhvit\YandexDisk\Python\telegram_bot_smm\system\actions\pars\parsing_group_members.py", line 35, in getting_user_data
    if isinstance(user.status(UserStatusRecently, UserStatusOnline, UserStatusLastWeek, UserStatusLastMonth)):
                  │    │      │                   │                 │                   └ <class 'telethon.tl.types.UserStatusLastMonth'>
                  │    │      │                   │                 └ <class 'telethon.tl.types.UserStatusLastWeek'>
                  │    │      │                   └ <class 'telethon.tl.types.UserStatusOnline'>
                  │    │      └ <class 'telethon.tl.types.UserStatusRecently'>
                  │    └ <telethon.tl.types.UserStatusOnline object at 0x000001FAA367F250>
                  └ <telethon.tl.types.User object at 0x000001FAA367F290>

TypeError: 'UserStatusOnline' object is not callable
