2023-11-23 12:31:56.383 | ERROR    | __main__:<module>:20 - Could not find a matching Constructor ID for the TLObject that was supposed to be read with ID abb5f120. See the FAQ for more details. Remaining bytes: b' \xf1\xb5\xab[\x1c\x00\x00\x10\x00\x00\x00JVvR\x00\x00\x00\x00\x07\xcf~\xfct\xe3b\x9d\x07Jo haab\tItsSevenB\x00\x00\x0c251906138874\x00\x00\x00?p\x8c\x00\xff\xf9^e\xe6)\x0bg\xf8\xe4\x17\xa3\x92\\5\xc8\xea0O]\xa4\xd7\xca1'
Traceback (most recent call last):

> File "C:\Users\zhvit\YandexDisk\Python\telegram_bot_smm\main.py", line 18, in <module>
    launching_the_program_with_account_verification()
    └ <function launching_the_program_with_account_verification at 0x000002CA792FB420>

  File "C:\Users\zhvit\YandexDisk\Python\telegram_bot_smm\main.py", line 12, in launching_the_program_with_account_verification
    deleting_files_by_dictionary()
    └ <function deleting_files_by_dictionary at 0x000002CA792E3E20>

  File "C:\Users\zhvit\YandexDisk\Python\telegram_bot_smm\system\telegram_actions\account_verification.py", line 25, in deleting_files_by_dictionary
    error_sessions = account_verification()
                     └ <function account_verification at 0x000002CA792E3F60>

  File "C:\Users\zhvit\YandexDisk\Python\telegram_bot_smm\system\telegram_actions\account_verification.py", line 61, in account_verification
    first_name, last_name, phone = account_name(client, name_account="me")
                                   │            └ <telethon.client.telegramclient.TelegramClient object at 0x000002CA793122D0>
                                   └ <function account_name at 0x000002CA77DDDEE0>

  File "C:\Users\zhvit\YandexDisk\Python\telegram_bot_smm\system\telegram_actions\telegram_actions.py", line 28, in account_name
    full = client(GetFullUserRequest(name_account))
           │      │                  └ 'me'
           │      └ <class 'telethon.tl.functions.users.GetFullUserRequest'>
           └ <telethon.client.telegramclient.TelegramClient object at 0x000002CA793122D0>

  File "C:\Users\zhvit\AppData\Local\Programs\Python\Python311\Lib\site-packages\telethon\sync.py", line 39, in syncified
    return loop.run_until_complete(coro)
           │    │                  └ <coroutine object UserMethods.__call__ at 0x000002CA793347C0>
           │    └ <function BaseEventLoop.run_until_complete at 0x000002CA75AD9B20>
           └ <ProactorEventLoop running=False closed=False debug=False>
  File "C:\Users\zhvit\AppData\Local\Programs\Python\Python311\Lib\asyncio\base_events.py", line 653, in run_until_complete
    return future.result()
           │      └ <method 'result' of '_asyncio.Task' objects>
           └ <Task finished name='Task-11' coro=<UserMethods.__call__() done, defined at C:\Users\zhvit\AppData\Local\Programs\Python\Pyth...
  File "C:\Users\zhvit\AppData\Local\Programs\Python\Python311\Lib\site-packages\telethon\client\users.py", line 30, in __call__
    return await self._call(self._sender, request, ordered=ordered)
                 │    │     │    │        │                └ False
                 │    │     │    │        └ <telethon.tl.functions.users.GetFullUserRequest object at 0x000002CA74103390>
                 │    │     │    └ <telethon.network.mtprotosender.MTProtoSender object at 0x000002CA79330F50>
                 │    │     └ <telethon.client.telegramclient.TelegramClient object at 0x000002CA793122D0>
                 │    └ <function UserMethods._call at 0x000002CA76258EA0>
                 └ <telethon.client.telegramclient.TelegramClient object at 0x000002CA793122D0>
  File "C:\Users\zhvit\AppData\Local\Programs\Python\Python311\Lib\site-packages\telethon\client\users.py", line 87, in _call
    result = await future
                   └ <Future finished exception=TypeNotFoundError("Could not find a matching Constructor ID for the TLObject that was supposed to ...
  File "C:\Users\zhvit\AppData\Local\Programs\Python\Python311\Lib\site-packages\telethon\network\mtprotosender.py", line 641, in _handle_rpc_result
    result = state.request.read_result(reader)
             │     │                   └ <telethon.extensions.binaryreader.BinaryReader object at 0x000002CA7931AF90>
             │     └ <member 'request' of 'RequestState' objects>
             └ <telethon.network.requeststate.RequestState object at 0x000002CA79325580>
  File "C:\Users\zhvit\AppData\Local\Programs\Python\Python311\Lib\site-packages\telethon\tl\tlobject.py", line 219, in read_result
    return reader.tgread_object()
           │      └ <function BinaryReader.tgread_object at 0x000002CA772B9C60>
           └ <telethon.extensions.binaryreader.BinaryReader object at 0x000002CA7931AF90>
  File "C:\Users\zhvit\AppData\Local\Programs\Python\Python311\Lib\site-packages\telethon\extensions\binaryreader.py", line 142, in tgread_object
    return clazz.from_reader(self)
           │     │           └ <telethon.extensions.binaryreader.BinaryReader object at 0x000002CA7931AF90>
           │     └ <classmethod(<function UserFull.from_reader at 0x000002CA76FDCFE0>)>
           └ <class 'telethon.tl.types.users.UserFull'>
  File "C:\Users\zhvit\AppData\Local\Programs\Python\Python311\Lib\site-packages\telethon\tl\types\users.py", line 52, in from_reader
    _x = reader.tgread_object()
         │      └ <function BinaryReader.tgread_object at 0x000002CA772B9C60>
         └ <telethon.extensions.binaryreader.BinaryReader object at 0x000002CA7931AF90>
  File "C:\Users\zhvit\AppData\Local\Programs\Python\Python311\Lib\site-packages\telethon\extensions\binaryreader.py", line 140, in tgread_object
    raise error
          └ TypeNotFoundError("Could not find a matching Constructor ID for the TLObject that was supposed to be read with ID abb5f120. S...

telethon.errors.common.TypeNotFoundError: Could not find a matching Constructor ID for the TLObject that was supposed to be read with ID abb5f120. See the FAQ for more details. Remaining bytes: b' \xf1\xb5\xab[\x1c\x00\x00\x10\x00\x00\x00JVvR\x00\x00\x00\x00\x07\xcf~\xfct\xe3b\x9d\x07Jo haab\tItsSevenB\x00\x00\x0c251906138874\x00\x00\x00?p\x8c\x00\xff\xf9^e\xe6)\x0bg\xf8\xe4\x17\xa3\x92\\5\xc8\xea0O]\xa4\xd7\xca1'
2023-11-23 12:31:56.383 | ERROR    | __main__:<module>:20 - Could not find a matching Constructor ID for the TLObject that was supposed to be read with ID abb5f120. See the FAQ for more details. Remaining bytes: b' \xf1\xb5\xab[\x1c\x00\x00\x10\x00\x00\x00JVvR\x00\x00\x00\x00\x07\xcf~\xfct\xe3b\x9d\x07Jo haab\tItsSevenB\x00\x00\x0c251906138874\x00\x00\x00?p\x8c\x00\xff\xf9^e\xe6)\x0bg\xf8\xe4\x17\xa3\x92\\5\xc8\xea0O]\xa4\xd7\xca1'
Traceback (most recent call last):

> File "C:\Users\zhvit\YandexDisk\Python\telegram_bot_smm\main.py", line 18, in <module>
    launching_the_program_with_account_verification()
    └ <function launching_the_program_with_account_verification at 0x000002CA792FB420>

  File "C:\Users\zhvit\YandexDisk\Python\telegram_bot_smm\main.py", line 12, in launching_the_program_with_account_verification
    deleting_files_by_dictionary()
    └ <function deleting_files_by_dictionary at 0x000002CA792E3E20>

  File "C:\Users\zhvit\YandexDisk\Python\telegram_bot_smm\system\telegram_actions\account_verification.py", line 25, in deleting_files_by_dictionary
    error_sessions = account_verification()
                     └ <function account_verification at 0x000002CA792E3F60>

  File "C:\Users\zhvit\YandexDisk\Python\telegram_bot_smm\system\telegram_actions\account_verification.py", line 61, in account_verification
    first_name, last_name, phone = account_name(client, name_account="me")
                                   │            └ <telethon.client.telegramclient.TelegramClient object at 0x000002CA793122D0>
                                   └ <function account_name at 0x000002CA77DDDEE0>

  File "C:\Users\zhvit\YandexDisk\Python\telegram_bot_smm\system\telegram_actions\telegram_actions.py", line 28, in account_name
    full = client(GetFullUserRequest(name_account))
           │      │                  └ 'me'
           │      └ <class 'telethon.tl.functions.users.GetFullUserRequest'>
           └ <telethon.client.telegramclient.TelegramClient object at 0x000002CA793122D0>

  File "C:\Users\zhvit\AppData\Local\Programs\Python\Python311\Lib\site-packages\telethon\sync.py", line 39, in syncified
    return loop.run_until_complete(coro)
           │    │                  └ <coroutine object UserMethods.__call__ at 0x000002CA793347C0>
           │    └ <function BaseEventLoop.run_until_complete at 0x000002CA75AD9B20>
           └ <ProactorEventLoop running=False closed=False debug=False>
  File "C:\Users\zhvit\AppData\Local\Programs\Python\Python311\Lib\asyncio\base_events.py", line 653, in run_until_complete
    return future.result()
           │      └ <method 'result' of '_asyncio.Task' objects>
           └ <Task finished name='Task-11' coro=<UserMethods.__call__() done, defined at C:\Users\zhvit\AppData\Local\Programs\Python\Pyth...
  File "C:\Users\zhvit\AppData\Local\Programs\Python\Python311\Lib\site-packages\telethon\client\users.py", line 30, in __call__
    return await self._call(self._sender, request, ordered=ordered)
                 │    │     │    │        │                └ False
                 │    │     │    │        └ <telethon.tl.functions.users.GetFullUserRequest object at 0x000002CA74103390>
                 │    │     │    └ <telethon.network.mtprotosender.MTProtoSender object at 0x000002CA79330F50>
                 │    │     └ <telethon.client.telegramclient.TelegramClient object at 0x000002CA793122D0>
                 │    └ <function UserMethods._call at 0x000002CA76258EA0>
                 └ <telethon.client.telegramclient.TelegramClient object at 0x000002CA793122D0>
  File "C:\Users\zhvit\AppData\Local\Programs\Python\Python311\Lib\site-packages\telethon\client\users.py", line 87, in _call
    result = await future
                   └ <Future finished exception=TypeNotFoundError("Could not find a matching Constructor ID for the TLObject that was supposed to ...
  File "C:\Users\zhvit\AppData\Local\Programs\Python\Python311\Lib\site-packages\telethon\network\mtprotosender.py", line 641, in _handle_rpc_result
    result = state.request.read_result(reader)
             │     │                   └ <telethon.extensions.binaryreader.BinaryReader object at 0x000002CA7931AF90>
             │     └ <member 'request' of 'RequestState' objects>
             └ <telethon.network.requeststate.RequestState object at 0x000002CA79325580>
  File "C:\Users\zhvit\AppData\Local\Programs\Python\Python311\Lib\site-packages\telethon\tl\tlobject.py", line 219, in read_result
    return reader.tgread_object()
           │      └ <function BinaryReader.tgread_object at 0x000002CA772B9C60>
           └ <telethon.extensions.binaryreader.BinaryReader object at 0x000002CA7931AF90>
  File "C:\Users\zhvit\AppData\Local\Programs\Python\Python311\Lib\site-packages\telethon\extensions\binaryreader.py", line 142, in tgread_object
    return clazz.from_reader(self)
           │     │           └ <telethon.extensions.binaryreader.BinaryReader object at 0x000002CA7931AF90>
           │     └ <classmethod(<function UserFull.from_reader at 0x000002CA76FDCFE0>)>
           └ <class 'telethon.tl.types.users.UserFull'>
  File "C:\Users\zhvit\AppData\Local\Programs\Python\Python311\Lib\site-packages\telethon\tl\types\users.py", line 52, in from_reader
    _x = reader.tgread_object()
         │      └ <function BinaryReader.tgread_object at 0x000002CA772B9C60>
         └ <telethon.extensions.binaryreader.BinaryReader object at 0x000002CA7931AF90>
  File "C:\Users\zhvit\AppData\Local\Programs\Python\Python311\Lib\site-packages\telethon\extensions\binaryreader.py", line 140, in tgread_object
    raise error
          └ TypeNotFoundError("Could not find a matching Constructor ID for the TLObject that was supposed to be read with ID abb5f120. S...

telethon.errors.common.TypeNotFoundError: Could not find a matching Constructor ID for the TLObject that was supposed to be read with ID abb5f120. See the FAQ for more details. Remaining bytes: b' \xf1\xb5\xab[\x1c\x00\x00\x10\x00\x00\x00JVvR\x00\x00\x00\x00\x07\xcf~\xfct\xe3b\x9d\x07Jo haab\tItsSevenB\x00\x00\x0c251906138874\x00\x00\x00?p\x8c\x00\xff\xf9^e\xe6)\x0bg\xf8\xe4\x17\xa3\x92\\5\xc8\xea0O]\xa4\xd7\xca1'
2023-11-23 16:32:11.799 | ERROR    | __main__:<module>:20 - RPCError -503: Timedout (caused by InvokeWithLayerRequest(InitConnectionRequest(GetConfigRequest)))
Traceback (most recent call last):

> File "C:\Users\zhvit\YandexDisk\Python\telegram_bot_smm\main.py", line 18, in <module>
    launching_the_program_with_account_verification()  # Проверка аккаунтов
    └ <function launching_the_program_with_account_verification at 0x00000164D977B380>

  File "C:\Users\zhvit\YandexDisk\Python\telegram_bot_smm\main.py", line 12, in launching_the_program_with_account_verification
    deleting_files_by_dictionary()
    └ <function deleting_files_by_dictionary at 0x00000164D975FD80>

  File "C:\Users\zhvit\YandexDisk\Python\telegram_bot_smm\system\telegram_actions\account_verification.py", line 25, in deleting_files_by_dictionary
    error_sessions = account_verification()
                     └ <function account_verification at 0x00000164D975FEC0>

  File "C:\Users\zhvit\YandexDisk\Python\telegram_bot_smm\system\telegram_actions\account_verification.py", line 54, in account_verification
    client.connect()  # Подсоединяемся к Telegram
    │      └ <function TelegramBaseClient.connect at 0x00000164D805AAC0>
    └ <telethon.client.telegramclient.TelegramClient object at 0x00000164D97F4E90>

  File "C:\Users\zhvit\AppData\Local\Programs\Python\Python311\Lib\site-packages\telethon\sync.py", line 39, in syncified
    return loop.run_until_complete(coro)
           │    │                  └ <coroutine object TelegramBaseClient.connect at 0x00000164D9750880>
           │    └ <function BaseEventLoop.run_until_complete at 0x00000164D5F59B20>
           └ <ProactorEventLoop running=False closed=False debug=False>
  File "C:\Users\zhvit\AppData\Local\Programs\Python\Python311\Lib\asyncio\base_events.py", line 653, in run_until_complete
    return future.result()
           │      └ <method 'result' of '_asyncio.Task' objects>
           └ <Task finished name='Task-1021' coro=<TelegramBaseClient.connect() done, defined at C:\Users\zhvit\AppData\Local\Programs\Pyt...
  File "C:\Users\zhvit\AppData\Local\Programs\Python\Python311\Lib\site-packages\telethon\client\telegrambaseclient.py", line 593, in connect
    await self._sender.send(functions.InvokeWithLayerRequest(LAYER, req))
          │    │       │    │         │                      │      └ <telethon.tl.functions.InitConnectionRequest object at 0x00000164D9832DD0>
          │    │       │    │         │                      └ 166
          │    │       │    │         └ <class 'telethon.tl.functions.InvokeWithLayerRequest'>
          │    │       │    └ <module 'telethon.tl.functions' from 'C:\\Users\\zhvit\\AppData\\Local\\Programs\\Python\\Python311\\Lib\\site-packages\\tele...
          │    │       └ <function MTProtoSender.send at 0x00000164D7B15440>
          │    └ <telethon.network.mtprotosender.MTProtoSender object at 0x00000164D9833A50>
          └ <telethon.client.telegramclient.TelegramClient object at 0x00000164D97F4E90>

telethon.errors.rpcbaseerrors.TimedOutError: RPCError -503: Timedout (caused by InvokeWithLayerRequest(InitConnectionRequest(GetConfigRequest)))
2023-11-23 16:32:11.799 | ERROR    | __main__:<module>:20 - RPCError -503: Timedout (caused by InvokeWithLayerRequest(InitConnectionRequest(GetConfigRequest)))
Traceback (most recent call last):

> File "C:\Users\zhvit\YandexDisk\Python\telegram_bot_smm\main.py", line 18, in <module>
    launching_the_program_with_account_verification()  # Проверка аккаунтов
    └ <function launching_the_program_with_account_verification at 0x00000164D977B380>

  File "C:\Users\zhvit\YandexDisk\Python\telegram_bot_smm\main.py", line 12, in launching_the_program_with_account_verification
    deleting_files_by_dictionary()
    └ <function deleting_files_by_dictionary at 0x00000164D975FD80>

  File "C:\Users\zhvit\YandexDisk\Python\telegram_bot_smm\system\telegram_actions\account_verification.py", line 25, in deleting_files_by_dictionary
    error_sessions = account_verification()
                     └ <function account_verification at 0x00000164D975FEC0>

  File "C:\Users\zhvit\YandexDisk\Python\telegram_bot_smm\system\telegram_actions\account_verification.py", line 54, in account_verification
    client.connect()  # Подсоединяемся к Telegram
    │      └ <function TelegramBaseClient.connect at 0x00000164D805AAC0>
    └ <telethon.client.telegramclient.TelegramClient object at 0x00000164D97F4E90>

  File "C:\Users\zhvit\AppData\Local\Programs\Python\Python311\Lib\site-packages\telethon\sync.py", line 39, in syncified
    return loop.run_until_complete(coro)
           │    │                  └ <coroutine object TelegramBaseClient.connect at 0x00000164D9750880>
           │    └ <function BaseEventLoop.run_until_complete at 0x00000164D5F59B20>
           └ <ProactorEventLoop running=False closed=False debug=False>
  File "C:\Users\zhvit\AppData\Local\Programs\Python\Python311\Lib\asyncio\base_events.py", line 653, in run_until_complete
    return future.result()
           │      └ <method 'result' of '_asyncio.Task' objects>
           └ <Task finished name='Task-1021' coro=<TelegramBaseClient.connect() done, defined at C:\Users\zhvit\AppData\Local\Programs\Pyt...
  File "C:\Users\zhvit\AppData\Local\Programs\Python\Python311\Lib\site-packages\telethon\client\telegrambaseclient.py", line 593, in connect
    await self._sender.send(functions.InvokeWithLayerRequest(LAYER, req))
          │    │       │    │         │                      │      └ <telethon.tl.functions.InitConnectionRequest object at 0x00000164D9832DD0>
          │    │       │    │         │                      └ 166
          │    │       │    │         └ <class 'telethon.tl.functions.InvokeWithLayerRequest'>
          │    │       │    └ <module 'telethon.tl.functions' from 'C:\\Users\\zhvit\\AppData\\Local\\Programs\\Python\\Python311\\Lib\\site-packages\\tele...
          │    │       └ <function MTProtoSender.send at 0x00000164D7B15440>
          │    └ <telethon.network.mtprotosender.MTProtoSender object at 0x00000164D9833A50>
          └ <telethon.client.telegramclient.TelegramClient object at 0x00000164D97F4E90>

telethon.errors.rpcbaseerrors.TimedOutError: RPCError -503: Timedout (caused by InvokeWithLayerRequest(InitConnectionRequest(GetConfigRequest)))
2023-11-24 15:42:04.541 | ERROR    | __main__:<module>:20 - Cannot send requests while disconnected
Traceback (most recent call last):

  File "C:\Users\zhvit\YandexDisk\Python\telegram_bot_smm\system\actions\subscription\subscription.py", line 78, in subscribe_to_group_or_channel
    client(JoinChannelRequest(groups_wrs))
    │      │                  └ 'https://t.me/megadym_community'
    │      └ <class 'telethon.tl.functions.channels.JoinChannelRequest'>
    └ <telethon.client.telegramclient.TelegramClient object at 0x0000016742233E90>

  File "C:\Users\zhvit\AppData\Local\Programs\Python\Python311\Lib\site-packages\telethon\sync.py", line 39, in syncified
    return loop.run_until_complete(coro)
           │    │                  └ <coroutine object UserMethods.__call__ at 0x0000016741E3D300>
           │    └ <function BaseEventLoop.run_until_complete at 0x000001673DE69B20>
           └ <ProactorEventLoop running=False closed=False debug=False>
  File "C:\Users\zhvit\AppData\Local\Programs\Python\Python311\Lib\asyncio\base_events.py", line 653, in run_until_complete
    return future.result()
           │      └ <method 'result' of '_asyncio.Task' objects>
           └ <Task finished name='Task-1874' coro=<UserMethods.__call__() done, defined at C:\Users\zhvit\AppData\Local\Programs\Python\Py...
  File "C:\Users\zhvit\AppData\Local\Programs\Python\Python311\Lib\site-packages\telethon\client\users.py", line 30, in __call__
    return await self._call(self._sender, request, ordered=ordered)
                 │    │     │    │        │                └ False
                 │    │     │    │        └ <telethon.tl.functions.channels.JoinChannelRequest object at 0x000001673BC89E90>
                 │    │     │    └ <telethon.network.mtprotosender.MTProtoSender object at 0x0000016742405810>
                 │    │     └ <telethon.client.telegramclient.TelegramClient object at 0x0000016742233E90>
                 │    └ <function UserMethods._call at 0x000001673E5ECEA0>
                 └ <telethon.client.telegramclient.TelegramClient object at 0x0000016742233E90>
  File "C:\Users\zhvit\AppData\Local\Programs\Python\Python311\Lib\site-packages\telethon\client\users.py", line 87, in _call
    result = await future
                   └ <Future finished exception=ChannelsTooMuchError('You have joined too many channels/supergroups (caused by JoinChannelRequest)')>

telethon.errors.rpcerrorlist.ChannelsTooMuchError: You have joined too many channels/supergroups (caused by JoinChannelRequest)


During handling of the above exception, another exception occurred:


Traceback (most recent call last):

> File "C:\Users\zhvit\YandexDisk\Python\telegram_bot_smm\main.py", line 18, in <module>
    launching_the_program_with_account_verification()  # Проверка аккаунтов
    └ <function launching_the_program_with_account_verification at 0x00000167416BBB00>

  File "C:\Users\zhvit\YandexDisk\Python\telegram_bot_smm\main.py", line 13, in launching_the_program_with_account_verification
    main_menu()  # Основное меню программы
    └ <function main_menu at 0x000001673BE3DEE0>

  File "C:\Users\zhvit\YandexDisk\Python\telegram_bot_smm\system\menu\main_menu_interface.py", line 41, in main_menu
    inviting_groups()
    └ <function inviting_groups at 0x00000167416BBBA0>

  File "C:\Users\zhvit\YandexDisk\Python\telegram_bot_smm\system\menu\main_menu_interface.py", line 81, in inviting_groups
    invite_from_multiple_accounts_with_limits(name_database_table="members")
    └ <function invite_from_multiple_accounts_with_limits at 0x00000167416A5BC0>

  File "C:\Users\zhvit\YandexDisk\Python\telegram_bot_smm\system\actions\invite\inviting_participants_telegram.py", line 71, in invite_from_multiple_accounts_with_limits
    subscribe_to_group_or_channel(client, link_group, phone)
    │                             │       │           └ '79063079801'
    │                             │       └ 'https://t.me/megadym_community'
    │                             └ <telethon.client.telegramclient.TelegramClient object at 0x0000016742233E90>
    └ <function subscribe_to_group_or_channel at 0x00000167416A59E0>

  File "C:\Users\zhvit\YandexDisk\Python\telegram_bot_smm\system\actions\subscription\subscription.py", line 86, in subscribe_to_group_or_channel
    client.delete_dialog(dialog)
    │      │             └ <telethon.tl.custom.dialog.Dialog object at 0x00000167424067D0>
    │      └ <function DialogMethods.delete_dialog at 0x000001673FFAAD40>
    └ <telethon.client.telegramclient.TelegramClient object at 0x0000016742233E90>

  File "C:\Users\zhvit\AppData\Local\Programs\Python\Python311\Lib\site-packages\telethon\sync.py", line 39, in syncified
    return loop.run_until_complete(coro)
           │    │                  └ <coroutine object DialogMethods.delete_dialog at 0x00000167416639A0>
           │    └ <function BaseEventLoop.run_until_complete at 0x000001673DE69B20>
           └ <ProactorEventLoop running=False closed=False debug=False>
  File "C:\Users\zhvit\AppData\Local\Programs\Python\Python311\Lib\asyncio\base_events.py", line 653, in run_until_complete
    return future.result()
           │      └ <method 'result' of '_asyncio.Task' objects>
           └ <Task finished name='Task-1884' coro=<DialogMethods.delete_dialog() done, defined at C:\Users\zhvit\AppData\Local\Programs\Py...
  File "C:\Users\zhvit\AppData\Local\Programs\Python\Python311\Lib\site-packages\telethon\client\dialogs.py", line 458, in delete_dialog
    return await self(functions.channels.LeaveChannelRequest(entity))
                 │    │         │        │                   └ <telethon.tl.types.InputPeerChannel object at 0x0000016741737FD0>
                 │    │         │        └ <class 'telethon.tl.functions.channels.LeaveChannelRequest'>
                 │    │         └ <module 'telethon.tl.functions.channels' from 'C:\\Users\\zhvit\\AppData\\Local\\Programs\\Python\\Python311\\Lib\\site-packa...
                 │    └ <module 'telethon.tl.functions' from 'C:\\Users\\zhvit\\AppData\\Local\\Programs\\Python\\Python311\\Lib\\site-packages\\tele...
                 └ <telethon.client.telegramclient.TelegramClient object at 0x0000016742233E90>
  File "C:\Users\zhvit\AppData\Local\Programs\Python\Python311\Lib\site-packages\telethon\client\users.py", line 30, in __call__
    return await self._call(self._sender, request, ordered=ordered)
                 │    │     │    │        │                └ False
                 │    │     │    │        └ <telethon.tl.functions.channels.LeaveChannelRequest object at 0x000001674230AB90>
                 │    │     │    └ <telethon.network.mtprotosender.MTProtoSender object at 0x0000016742405810>
                 │    │     └ <telethon.client.telegramclient.TelegramClient object at 0x0000016742233E90>
                 │    └ <function UserMethods._call at 0x000001673E5ECEA0>
                 └ <telethon.client.telegramclient.TelegramClient object at 0x0000016742233E90>
  File "C:\Users\zhvit\AppData\Local\Programs\Python\Python311\Lib\site-packages\telethon\client\users.py", line 67, in _call
    future = sender.send(request, ordered=ordered)
             │      │    │                └ False
             │      │    └ <telethon.tl.functions.channels.LeaveChannelRequest object at 0x000001674230AB90>
             │      └ <function MTProtoSender.send at 0x000001673FB15440>
             └ <telethon.network.mtprotosender.MTProtoSender object at 0x0000016742405810>
  File "C:\Users\zhvit\AppData\Local\Programs\Python\Python311\Lib\site-packages\telethon\network\mtprotosender.py", line 179, in send
    raise ConnectionError('Cannot send requests while disconnected')

ConnectionError: Cannot send requests while disconnected
2023-11-24 15:42:04.541 | ERROR    | __main__:<module>:20 - Cannot send requests while disconnected
Traceback (most recent call last):

  File "C:\Users\zhvit\YandexDisk\Python\telegram_bot_smm\system\actions\subscription\subscription.py", line 78, in subscribe_to_group_or_channel
    client(JoinChannelRequest(groups_wrs))
    │      │                  └ 'https://t.me/megadym_community'
    │      └ <class 'telethon.tl.functions.channels.JoinChannelRequest'>
    └ <telethon.client.telegramclient.TelegramClient object at 0x0000016742233E90>

  File "C:\Users\zhvit\AppData\Local\Programs\Python\Python311\Lib\site-packages\telethon\sync.py", line 39, in syncified
    return loop.run_until_complete(coro)
           │    │                  └ <coroutine object UserMethods.__call__ at 0x0000016741E3D300>
           │    └ <function BaseEventLoop.run_until_complete at 0x000001673DE69B20>
           └ <ProactorEventLoop running=False closed=False debug=False>
  File "C:\Users\zhvit\AppData\Local\Programs\Python\Python311\Lib\asyncio\base_events.py", line 653, in run_until_complete
    return future.result()
           │      └ <method 'result' of '_asyncio.Task' objects>
           └ <Task finished name='Task-1874' coro=<UserMethods.__call__() done, defined at C:\Users\zhvit\AppData\Local\Programs\Python\Py...
  File "C:\Users\zhvit\AppData\Local\Programs\Python\Python311\Lib\site-packages\telethon\client\users.py", line 30, in __call__
    return await self._call(self._sender, request, ordered=ordered)
                 │    │     │    │        │                └ False
                 │    │     │    │        └ <telethon.tl.functions.channels.JoinChannelRequest object at 0x000001673BC89E90>
                 │    │     │    └ <telethon.network.mtprotosender.MTProtoSender object at 0x0000016742405810>
                 │    │     └ <telethon.client.telegramclient.TelegramClient object at 0x0000016742233E90>
                 │    └ <function UserMethods._call at 0x000001673E5ECEA0>
                 └ <telethon.client.telegramclient.TelegramClient object at 0x0000016742233E90>
  File "C:\Users\zhvit\AppData\Local\Programs\Python\Python311\Lib\site-packages\telethon\client\users.py", line 87, in _call
    result = await future
                   └ <Future finished exception=ChannelsTooMuchError('You have joined too many channels/supergroups (caused by JoinChannelRequest)')>

telethon.errors.rpcerrorlist.ChannelsTooMuchError: You have joined too many channels/supergroups (caused by JoinChannelRequest)


During handling of the above exception, another exception occurred:


Traceback (most recent call last):

> File "C:\Users\zhvit\YandexDisk\Python\telegram_bot_smm\main.py", line 18, in <module>
    launching_the_program_with_account_verification()  # Проверка аккаунтов
    └ <function launching_the_program_with_account_verification at 0x00000167416BBB00>

  File "C:\Users\zhvit\YandexDisk\Python\telegram_bot_smm\main.py", line 13, in launching_the_program_with_account_verification
    main_menu()  # Основное меню программы
    └ <function main_menu at 0x000001673BE3DEE0>

  File "C:\Users\zhvit\YandexDisk\Python\telegram_bot_smm\system\menu\main_menu_interface.py", line 41, in main_menu
    inviting_groups()
    └ <function inviting_groups at 0x00000167416BBBA0>

  File "C:\Users\zhvit\YandexDisk\Python\telegram_bot_smm\system\menu\main_menu_interface.py", line 81, in inviting_groups
    invite_from_multiple_accounts_with_limits(name_database_table="members")
    └ <function invite_from_multiple_accounts_with_limits at 0x00000167416A5BC0>

  File "C:\Users\zhvit\YandexDisk\Python\telegram_bot_smm\system\actions\invite\inviting_participants_telegram.py", line 71, in invite_from_multiple_accounts_with_limits
    subscribe_to_group_or_channel(client, link_group, phone)
    │                             │       │           └ '79063079801'
    │                             │       └ 'https://t.me/megadym_community'
    │                             └ <telethon.client.telegramclient.TelegramClient object at 0x0000016742233E90>
    └ <function subscribe_to_group_or_channel at 0x00000167416A59E0>

  File "C:\Users\zhvit\YandexDisk\Python\telegram_bot_smm\system\actions\subscription\subscription.py", line 86, in subscribe_to_group_or_channel
    client.delete_dialog(dialog)
    │      │             └ <telethon.tl.custom.dialog.Dialog object at 0x00000167424067D0>
    │      └ <function DialogMethods.delete_dialog at 0x000001673FFAAD40>
    └ <telethon.client.telegramclient.TelegramClient object at 0x0000016742233E90>

  File "C:\Users\zhvit\AppData\Local\Programs\Python\Python311\Lib\site-packages\telethon\sync.py", line 39, in syncified
    return loop.run_until_complete(coro)
           │    │                  └ <coroutine object DialogMethods.delete_dialog at 0x00000167416639A0>
           │    └ <function BaseEventLoop.run_until_complete at 0x000001673DE69B20>
           └ <ProactorEventLoop running=False closed=False debug=False>
  File "C:\Users\zhvit\AppData\Local\Programs\Python\Python311\Lib\asyncio\base_events.py", line 653, in run_until_complete
    return future.result()
           │      └ <method 'result' of '_asyncio.Task' objects>
           └ <Task finished name='Task-1884' coro=<DialogMethods.delete_dialog() done, defined at C:\Users\zhvit\AppData\Local\Programs\Py...
  File "C:\Users\zhvit\AppData\Local\Programs\Python\Python311\Lib\site-packages\telethon\client\dialogs.py", line 458, in delete_dialog
    return await self(functions.channels.LeaveChannelRequest(entity))
                 │    │         │        │                   └ <telethon.tl.types.InputPeerChannel object at 0x0000016741737FD0>
                 │    │         │        └ <class 'telethon.tl.functions.channels.LeaveChannelRequest'>
                 │    │         └ <module 'telethon.tl.functions.channels' from 'C:\\Users\\zhvit\\AppData\\Local\\Programs\\Python\\Python311\\Lib\\site-packa...
                 │    └ <module 'telethon.tl.functions' from 'C:\\Users\\zhvit\\AppData\\Local\\Programs\\Python\\Python311\\Lib\\site-packages\\tele...
                 └ <telethon.client.telegramclient.TelegramClient object at 0x0000016742233E90>
  File "C:\Users\zhvit\AppData\Local\Programs\Python\Python311\Lib\site-packages\telethon\client\users.py", line 30, in __call__
    return await self._call(self._sender, request, ordered=ordered)
                 │    │     │    │        │                └ False
                 │    │     │    │        └ <telethon.tl.functions.channels.LeaveChannelRequest object at 0x000001674230AB90>
                 │    │     │    └ <telethon.network.mtprotosender.MTProtoSender object at 0x0000016742405810>
                 │    │     └ <telethon.client.telegramclient.TelegramClient object at 0x0000016742233E90>
                 │    └ <function UserMethods._call at 0x000001673E5ECEA0>
                 └ <telethon.client.telegramclient.TelegramClient object at 0x0000016742233E90>
  File "C:\Users\zhvit\AppData\Local\Programs\Python\Python311\Lib\site-packages\telethon\client\users.py", line 67, in _call
    future = sender.send(request, ordered=ordered)
             │      │    │                └ False
             │      │    └ <telethon.tl.functions.channels.LeaveChannelRequest object at 0x000001674230AB90>
             │      └ <function MTProtoSender.send at 0x000001673FB15440>
             └ <telethon.network.mtprotosender.MTProtoSender object at 0x0000016742405810>
  File "C:\Users\zhvit\AppData\Local\Programs\Python\Python311\Lib\site-packages\telethon\network\mtprotosender.py", line 179, in send
    raise ConnectionError('Cannot send requests while disconnected')

ConnectionError: Cannot send requests while disconnected
2023-11-26 23:43:15.681 | ERROR    | __main__:<module>:20 - Cannot send requests while disconnected
Traceback (most recent call last):

  File "C:\Users\zhvit\YandexDisk\Python\telegram_bot_smm\system\actions\subscription\subscription.py", line 78, in subscribe_to_group_or_channel
    client(JoinChannelRequest(groups_wrs))
    │      │                  └ 'https://t.me/megadym_community'
    │      └ <class 'telethon.tl.functions.channels.JoinChannelRequest'>
    └ <telethon.client.telegramclient.TelegramClient object at 0x00000188AC4FC450>

  File "C:\Users\zhvit\AppData\Local\Programs\Python\Python311\Lib\site-packages\telethon\sync.py", line 39, in syncified
    return loop.run_until_complete(coro)
           │    │                  └ <coroutine object UserMethods.__call__ at 0x00000188AC7CE7A0>
           │    └ <function BaseEventLoop.run_until_complete at 0x00000188A8BCD6C0>
           └ <ProactorEventLoop running=False closed=False debug=False>
  File "C:\Users\zhvit\AppData\Local\Programs\Python\Python311\Lib\asyncio\base_events.py", line 653, in run_until_complete
    return future.result()
           │      └ <method 'result' of '_asyncio.Task' objects>
           └ <Task finished name='Task-3563' coro=<UserMethods.__call__() done, defined at C:\Users\zhvit\AppData\Local\Programs\Python\Py...
  File "C:\Users\zhvit\AppData\Local\Programs\Python\Python311\Lib\site-packages\telethon\client\users.py", line 30, in __call__
    return await self._call(self._sender, request, ordered=ordered)
                 │    │     │    │        │                └ False
                 │    │     │    │        └ <telethon.tl.functions.channels.JoinChannelRequest object at 0x00000188AC4FFD10>
                 │    │     │    └ <telethon.network.mtprotosender.MTProtoSender object at 0x00000188AC6882D0>
                 │    │     └ <telethon.client.telegramclient.TelegramClient object at 0x00000188AC4FC450>
                 │    └ <function UserMethods._call at 0x00000188AA618680>
                 └ <telethon.client.telegramclient.TelegramClient object at 0x00000188AC4FC450>
  File "C:\Users\zhvit\AppData\Local\Programs\Python\Python311\Lib\site-packages\telethon\client\users.py", line 87, in _call
    result = await future
                   └ <Future finished exception=ChannelsTooMuchError('You have joined too many channels/supergroups (caused by JoinChannelRequest)')>

telethon.errors.rpcerrorlist.ChannelsTooMuchError: You have joined too many channels/supergroups (caused by JoinChannelRequest)


During handling of the above exception, another exception occurred:


Traceback (most recent call last):

> File "C:\Users\zhvit\YandexDisk\Python\telegram_bot_smm\main.py", line 18, in <module>
    launching_the_program_with_account_verification()  # Проверка аккаунтов
    └ <function launching_the_program_with_account_verification at 0x00000188AC4B5080>

  File "C:\Users\zhvit\YandexDisk\Python\telegram_bot_smm\main.py", line 13, in launching_the_program_with_account_verification
    main_menu()  # Основное меню программы
    └ <function main_menu at 0x00000188A6B6CE00>

  File "C:\Users\zhvit\YandexDisk\Python\telegram_bot_smm\system\menu\main_menu_interface.py", line 41, in main_menu
    inviting_groups()
    └ <function inviting_groups at 0x00000188AC4B5120>

  File "C:\Users\zhvit\YandexDisk\Python\telegram_bot_smm\system\menu\main_menu_interface.py", line 91, in inviting_groups
    launching_an_invite_every_day_at_a_certain_time()
    └ <function launching_an_invite_every_day_at_a_certain_time at 0x00000188AC4A5800>

  File "C:\Users\zhvit\YandexDisk\Python\telegram_bot_smm\system\actions\invite\telegram_invite_scheduler.py", line 22, in launching_an_invite_every_day_at_a_certain_time
    schedule.run_pending()
    │        └ <function run_pending at 0x00000188AC4A5260>
    └ <module 'schedule' from 'C:\\Users\\zhvit\\AppData\\Local\\Programs\\Python\\Python311\\Lib\\site-packages\\schedule\\__init_...

  File "C:\Users\zhvit\AppData\Local\Programs\Python\Python311\Lib\site-packages\schedule\__init__.py", line 822, in run_pending
    default_scheduler.run_pending()
    │                 └ <function Scheduler.run_pending at 0x00000188AC493920>
    └ <schedule.Scheduler object at 0x00000188AC4A0910>
  File "C:\Users\zhvit\AppData\Local\Programs\Python\Python311\Lib\site-packages\schedule\__init__.py", line 100, in run_pending
    self._run_job(job)
    │    │        └ Every 1 day at 23:35:00 do schedule_member_invitation() (last run: [never], next run: 2023-11-26 23:35:00)
    │    └ <function Scheduler._run_job at 0x00000188AC493CE0>
    └ <schedule.Scheduler object at 0x00000188AC4A0910>
  File "C:\Users\zhvit\AppData\Local\Programs\Python\Python311\Lib\site-packages\schedule\__init__.py", line 172, in _run_job
    ret = job.run()
          │   └ <function Job.run at 0x00000188AC4A4FE0>
          └ Every 1 day at 23:35:00 do schedule_member_invitation() (last run: [never], next run: 2023-11-26 23:35:00)
  File "C:\Users\zhvit\AppData\Local\Programs\Python\Python311\Lib\site-packages\schedule\__init__.py", line 693, in run
    ret = self.job_func()
          │    └ functools.partial(<function schedule_member_invitation at 0x00000188AC493240>)
          └ Every 1 day at 23:35:00 do schedule_member_invitation() (last run: [never], next run: 2023-11-26 23:35:00)

  File "C:\Users\zhvit\YandexDisk\Python\telegram_bot_smm\system\actions\invite\telegram_invite_scheduler.py", line 14, in schedule_member_invitation
    invitation_from_all_accounts_program_body(name_database_table="members")
    └ <function invitation_from_all_accounts_program_body at 0x00000188AC422CA0>

  File "C:\Users\zhvit\YandexDisk\Python\telegram_bot_smm\system\actions\invite\inviting_participants_telegram.py", line 40, in invitation_from_all_accounts_program_body
    subscribe_to_group_or_channel(client, link_group, phone)
    │                             │       │           └ '79063079801'
    │                             │       └ 'https://t.me/megadym_community'
    │                             └ <telethon.client.telegramclient.TelegramClient object at 0x00000188AC4FC450>
    └ <function subscribe_to_group_or_channel at 0x00000188AC492CA0>

  File "C:\Users\zhvit\YandexDisk\Python\telegram_bot_smm\system\actions\subscription\subscription.py", line 86, in subscribe_to_group_or_channel
    client.delete_dialog(dialog)
    │      │             └ <telethon.tl.custom.dialog.Dialog object at 0x00000188AC4F8310>
    │      └ <function DialogMethods.delete_dialog at 0x00000188AAD7C220>
    └ <telethon.client.telegramclient.TelegramClient object at 0x00000188AC4FC450>

  File "C:\Users\zhvit\AppData\Local\Programs\Python\Python311\Lib\site-packages\telethon\sync.py", line 39, in syncified
    return loop.run_until_complete(coro)
           │    │                  └ <coroutine object DialogMethods.delete_dialog at 0x00000188AC4BA8A0>
           │    └ <function BaseEventLoop.run_until_complete at 0x00000188A8BCD6C0>
           └ <ProactorEventLoop running=False closed=False debug=False>
  File "C:\Users\zhvit\AppData\Local\Programs\Python\Python311\Lib\asyncio\base_events.py", line 653, in run_until_complete
    return future.result()
           │      └ <method 'result' of '_asyncio.Task' objects>
           └ <Task finished name='Task-3570' coro=<DialogMethods.delete_dialog() done, defined at C:\Users\zhvit\AppData\Local\Programs\Py...
  File "C:\Users\zhvit\AppData\Local\Programs\Python\Python311\Lib\site-packages\telethon\client\dialogs.py", line 458, in delete_dialog
    return await self(functions.channels.LeaveChannelRequest(entity))
                 │    │         │        │                   └ <telethon.tl.types.InputPeerChannel object at 0x00000188AD3202D0>
                 │    │         │        └ <class 'telethon.tl.functions.channels.LeaveChannelRequest'>
                 │    │         └ <module 'telethon.tl.functions.channels' from 'C:\\Users\\zhvit\\AppData\\Local\\Programs\\Python\\Python311\\Lib\\site-packa...
                 │    └ <module 'telethon.tl.functions' from 'C:\\Users\\zhvit\\AppData\\Local\\Programs\\Python\\Python311\\Lib\\site-packages\\tele...
                 └ <telethon.client.telegramclient.TelegramClient object at 0x00000188AC4FC450>
  File "C:\Users\zhvit\AppData\Local\Programs\Python\Python311\Lib\site-packages\telethon\client\users.py", line 30, in __call__
    return await self._call(self._sender, request, ordered=ordered)
                 │    │     │    │        │                └ False
                 │    │     │    │        └ <telethon.tl.functions.channels.LeaveChannelRequest object at 0x00000188AC4D7E90>
                 │    │     │    └ <telethon.network.mtprotosender.MTProtoSender object at 0x00000188AC6882D0>
                 │    │     └ <telethon.client.telegramclient.TelegramClient object at 0x00000188AC4FC450>
                 │    └ <function UserMethods._call at 0x00000188AA618680>
                 └ <telethon.client.telegramclient.TelegramClient object at 0x00000188AC4FC450>
  File "C:\Users\zhvit\AppData\Local\Programs\Python\Python311\Lib\site-packages\telethon\client\users.py", line 67, in _call
    future = sender.send(request, ordered=ordered)
             │      │    │                └ False
             │      │    └ <telethon.tl.functions.channels.LeaveChannelRequest object at 0x00000188AC4D7E90>
             │      └ <function MTProtoSender.send at 0x00000188AA75A3E0>
             └ <telethon.network.mtprotosender.MTProtoSender object at 0x00000188AC6882D0>
  File "C:\Users\zhvit\AppData\Local\Programs\Python\Python311\Lib\site-packages\telethon\network\mtprotosender.py", line 179, in send
    raise ConnectionError('Cannot send requests while disconnected')

ConnectionError: Cannot send requests while disconnected
2023-11-26 23:43:15.681 | ERROR    | __main__:<module>:20 - Cannot send requests while disconnected
Traceback (most recent call last):

  File "C:\Users\zhvit\YandexDisk\Python\telegram_bot_smm\system\actions\subscription\subscription.py", line 78, in subscribe_to_group_or_channel
    client(JoinChannelRequest(groups_wrs))
    │      │                  └ 'https://t.me/megadym_community'
    │      └ <class 'telethon.tl.functions.channels.JoinChannelRequest'>
    └ <telethon.client.telegramclient.TelegramClient object at 0x00000188AC4FC450>

  File "C:\Users\zhvit\AppData\Local\Programs\Python\Python311\Lib\site-packages\telethon\sync.py", line 39, in syncified
    return loop.run_until_complete(coro)
           │    │                  └ <coroutine object UserMethods.__call__ at 0x00000188AC7CE7A0>
           │    └ <function BaseEventLoop.run_until_complete at 0x00000188A8BCD6C0>
           └ <ProactorEventLoop running=False closed=False debug=False>
  File "C:\Users\zhvit\AppData\Local\Programs\Python\Python311\Lib\asyncio\base_events.py", line 653, in run_until_complete
    return future.result()
           │      └ <method 'result' of '_asyncio.Task' objects>
           └ <Task finished name='Task-3563' coro=<UserMethods.__call__() done, defined at C:\Users\zhvit\AppData\Local\Programs\Python\Py...
  File "C:\Users\zhvit\AppData\Local\Programs\Python\Python311\Lib\site-packages\telethon\client\users.py", line 30, in __call__
    return await self._call(self._sender, request, ordered=ordered)
                 │    │     │    │        │                └ False
                 │    │     │    │        └ <telethon.tl.functions.channels.JoinChannelRequest object at 0x00000188AC4FFD10>
                 │    │     │    └ <telethon.network.mtprotosender.MTProtoSender object at 0x00000188AC6882D0>
                 │    │     └ <telethon.client.telegramclient.TelegramClient object at 0x00000188AC4FC450>
                 │    └ <function UserMethods._call at 0x00000188AA618680>
                 └ <telethon.client.telegramclient.TelegramClient object at 0x00000188AC4FC450>
  File "C:\Users\zhvit\AppData\Local\Programs\Python\Python311\Lib\site-packages\telethon\client\users.py", line 87, in _call
    result = await future
                   └ <Future finished exception=ChannelsTooMuchError('You have joined too many channels/supergroups (caused by JoinChannelRequest)')>

telethon.errors.rpcerrorlist.ChannelsTooMuchError: You have joined too many channels/supergroups (caused by JoinChannelRequest)


During handling of the above exception, another exception occurred:


Traceback (most recent call last):

> File "C:\Users\zhvit\YandexDisk\Python\telegram_bot_smm\main.py", line 18, in <module>
    launching_the_program_with_account_verification()  # Проверка аккаунтов
    └ <function launching_the_program_with_account_verification at 0x00000188AC4B5080>

  File "C:\Users\zhvit\YandexDisk\Python\telegram_bot_smm\main.py", line 13, in launching_the_program_with_account_verification
    main_menu()  # Основное меню программы
    └ <function main_menu at 0x00000188A6B6CE00>

  File "C:\Users\zhvit\YandexDisk\Python\telegram_bot_smm\system\menu\main_menu_interface.py", line 41, in main_menu
    inviting_groups()
    └ <function inviting_groups at 0x00000188AC4B5120>

  File "C:\Users\zhvit\YandexDisk\Python\telegram_bot_smm\system\menu\main_menu_interface.py", line 91, in inviting_groups
    launching_an_invite_every_day_at_a_certain_time()
    └ <function launching_an_invite_every_day_at_a_certain_time at 0x00000188AC4A5800>

  File "C:\Users\zhvit\YandexDisk\Python\telegram_bot_smm\system\actions\invite\telegram_invite_scheduler.py", line 22, in launching_an_invite_every_day_at_a_certain_time
    schedule.run_pending()
    │        └ <function run_pending at 0x00000188AC4A5260>
    └ <module 'schedule' from 'C:\\Users\\zhvit\\AppData\\Local\\Programs\\Python\\Python311\\Lib\\site-packages\\schedule\\__init_...

  File "C:\Users\zhvit\AppData\Local\Programs\Python\Python311\Lib\site-packages\schedule\__init__.py", line 822, in run_pending
    default_scheduler.run_pending()
    │                 └ <function Scheduler.run_pending at 0x00000188AC493920>
    └ <schedule.Scheduler object at 0x00000188AC4A0910>
  File "C:\Users\zhvit\AppData\Local\Programs\Python\Python311\Lib\site-packages\schedule\__init__.py", line 100, in run_pending
    self._run_job(job)
    │    │        └ Every 1 day at 23:35:00 do schedule_member_invitation() (last run: [never], next run: 2023-11-26 23:35:00)
    │    └ <function Scheduler._run_job at 0x00000188AC493CE0>
    └ <schedule.Scheduler object at 0x00000188AC4A0910>
  File "C:\Users\zhvit\AppData\Local\Programs\Python\Python311\Lib\site-packages\schedule\__init__.py", line 172, in _run_job
    ret = job.run()
          │   └ <function Job.run at 0x00000188AC4A4FE0>
          └ Every 1 day at 23:35:00 do schedule_member_invitation() (last run: [never], next run: 2023-11-26 23:35:00)
  File "C:\Users\zhvit\AppData\Local\Programs\Python\Python311\Lib\site-packages\schedule\__init__.py", line 693, in run
    ret = self.job_func()
          │    └ functools.partial(<function schedule_member_invitation at 0x00000188AC493240>)
          └ Every 1 day at 23:35:00 do schedule_member_invitation() (last run: [never], next run: 2023-11-26 23:35:00)

  File "C:\Users\zhvit\YandexDisk\Python\telegram_bot_smm\system\actions\invite\telegram_invite_scheduler.py", line 14, in schedule_member_invitation
    invitation_from_all_accounts_program_body(name_database_table="members")
    └ <function invitation_from_all_accounts_program_body at 0x00000188AC422CA0>

  File "C:\Users\zhvit\YandexDisk\Python\telegram_bot_smm\system\actions\invite\inviting_participants_telegram.py", line 40, in invitation_from_all_accounts_program_body
    subscribe_to_group_or_channel(client, link_group, phone)
    │                             │       │           └ '79063079801'
    │                             │       └ 'https://t.me/megadym_community'
    │                             └ <telethon.client.telegramclient.TelegramClient object at 0x00000188AC4FC450>
    └ <function subscribe_to_group_or_channel at 0x00000188AC492CA0>

  File "C:\Users\zhvit\YandexDisk\Python\telegram_bot_smm\system\actions\subscription\subscription.py", line 86, in subscribe_to_group_or_channel
    client.delete_dialog(dialog)
    │      │             └ <telethon.tl.custom.dialog.Dialog object at 0x00000188AC4F8310>
    │      └ <function DialogMethods.delete_dialog at 0x00000188AAD7C220>
    └ <telethon.client.telegramclient.TelegramClient object at 0x00000188AC4FC450>

  File "C:\Users\zhvit\AppData\Local\Programs\Python\Python311\Lib\site-packages\telethon\sync.py", line 39, in syncified
    return loop.run_until_complete(coro)
           │    │                  └ <coroutine object DialogMethods.delete_dialog at 0x00000188AC4BA8A0>
           │    └ <function BaseEventLoop.run_until_complete at 0x00000188A8BCD6C0>
           └ <ProactorEventLoop running=False closed=False debug=False>
  File "C:\Users\zhvit\AppData\Local\Programs\Python\Python311\Lib\asyncio\base_events.py", line 653, in run_until_complete
    return future.result()
           │      └ <method 'result' of '_asyncio.Task' objects>
           └ <Task finished name='Task-3570' coro=<DialogMethods.delete_dialog() done, defined at C:\Users\zhvit\AppData\Local\Programs\Py...
  File "C:\Users\zhvit\AppData\Local\Programs\Python\Python311\Lib\site-packages\telethon\client\dialogs.py", line 458, in delete_dialog
    return await self(functions.channels.LeaveChannelRequest(entity))
                 │    │         │        │                   └ <telethon.tl.types.InputPeerChannel object at 0x00000188AD3202D0>
                 │    │         │        └ <class 'telethon.tl.functions.channels.LeaveChannelRequest'>
                 │    │         └ <module 'telethon.tl.functions.channels' from 'C:\\Users\\zhvit\\AppData\\Local\\Programs\\Python\\Python311\\Lib\\site-packa...
                 │    └ <module 'telethon.tl.functions' from 'C:\\Users\\zhvit\\AppData\\Local\\Programs\\Python\\Python311\\Lib\\site-packages\\tele...
                 └ <telethon.client.telegramclient.TelegramClient object at 0x00000188AC4FC450>
  File "C:\Users\zhvit\AppData\Local\Programs\Python\Python311\Lib\site-packages\telethon\client\users.py", line 30, in __call__
    return await self._call(self._sender, request, ordered=ordered)
                 │    │     │    │        │                └ False
                 │    │     │    │        └ <telethon.tl.functions.channels.LeaveChannelRequest object at 0x00000188AC4D7E90>
                 │    │     │    └ <telethon.network.mtprotosender.MTProtoSender object at 0x00000188AC6882D0>
                 │    │     └ <telethon.client.telegramclient.TelegramClient object at 0x00000188AC4FC450>
                 │    └ <function UserMethods._call at 0x00000188AA618680>
                 └ <telethon.client.telegramclient.TelegramClient object at 0x00000188AC4FC450>
  File "C:\Users\zhvit\AppData\Local\Programs\Python\Python311\Lib\site-packages\telethon\client\users.py", line 67, in _call
    future = sender.send(request, ordered=ordered)
             │      │    │                └ False
             │      │    └ <telethon.tl.functions.channels.LeaveChannelRequest object at 0x00000188AC4D7E90>
             │      └ <function MTProtoSender.send at 0x00000188AA75A3E0>
             └ <telethon.network.mtprotosender.MTProtoSender object at 0x00000188AC6882D0>
  File "C:\Users\zhvit\AppData\Local\Programs\Python\Python311\Lib\site-packages\telethon\network\mtprotosender.py", line 179, in send
    raise ConnectionError('Cannot send requests while disconnected')

ConnectionError: Cannot send requests while disconnected
